Workbook

Sheet 说明
B2: 饮食追踪系统 · v0.2（配方联动版）
B3: 配方营养已和食材库联动：在配方明细填食材克数 → 自动加总。改食材库的数，所有相关配方跟着变。
B5: 颜色规则（先看这个）
B6: 黄色格 | C6: 你要填或替换的。食材库营养现在是参考值占位，拍到成分表后逐个换成你的实测值。
B7: 浅蓝格 | C7: 公式自动算的，别手改（改了就断了联动）。
B8: 白色格 | C8: 普通可编辑：配方的食材克数、份数、备注，按你实际做法改。
B10: 三层怎么联动（这是这版的核心）
B11: ①食材库 | C11: 数据源。每样食材的营养统一按「每100g」。计件的（鸡蛋、面包片等）已换算成每100g，备注里写了每个约多少克。
B12: ②配方明细 | C12: 你填「这道菜用了哪些食材、各多少克」。旁边自动从食材库查出营养、算出每项贡献。一道菜占连续几行。
B13: ③配方汇总 | C13: 每道菜一行，自动把明细里属于它的食材加总=整锅营养，再除份数=每份。这就是生重相加。
B14: 怎么用 | C14: 做饭=照③选一道做；吃=这顿吃了整锅几分之一，乘一下；之后接每日记录对账（下一层）。
B16: 为什么是生重相加（你问过）
B17: 原理 | C17: 炖煮只是脱水，重量变但总热量不变。只要下锅前的东西都按生重记了，加起来就是整锅热量。
B18: 唯一的洞 | C18: 额外加进锅的油/糖/酱要记进去，否则漏算。你几乎不炒、只喷底油，这个洞很小，喷油那几kcal可忽略。
B20: 数据准确度
B21: 营养值 | C21: 现在是通用数据库参考值，占位用。品牌差异大的（豆腐/牛腩/酸奶/面包/坚果/咖喱）尤其要换成你的实测。
B22: 成分表换算 | C22: 美国成分表按每份(serving)标，包装上有每份克重。换算成每100g：每份值 ÷ 每份克重 × 100，填进食材库。
B23: 称量 | C23: 秤只用在热量密集项（主食、油、肉、坚果、牛油果、酱）。蔬菜目测。
B25: 下一步
B26: 待你做 | C26: 1) 删改增配方明细的食材和克数；2) 配方汇总填「典型份数」（你那锅实际吃几顿）；3) 慢慢替换食材库营养。
B27: 待搭 | C27: 每日记录层（消化「目标vs实际」的对账）+ 采购清点层。两者都从同一套食材/配方引用接出去。

Sheet ①食材库
A1: ① 食材库 — 营养统一按每100g，黄色=参考值占位待替换
A2: 类别 | B2: 食材 | C2: 热量/100g | D2: 蛋白/100g | E2: 碳水/100g | F2: 脂肪/100g | G2: 包装规格(美超) | H2: 存储 | I2: 久放可清点 | J2: 备注(含计件克重)
A3: 蛋白质
A4: 蛋白质 | B4: 鸡胸肉(生) | C4: 120 | D4: 23 | E4: 0 | F4: 2.6 | G4: family pack 2-3 lb | H4: 冷冻可 | I4: 是
A5: 蛋白质 | B5: 鸡腿肉去皮(生) | C5: 120 | D5: 20 | E5: 0 | F5: 4 | G5: 按 lb | H5: 冷冻可 | I5: 是
A6: 蛋白质 | B6: 带皮鸡腿(生) | C6: 215 | D6: 18 | E6: 0 | F6: 15 | G6: 按 lb | H6: 冷冻可 | I6: 是 | J6: 贴纸标少吃
A7: 蛋白质 | B7: 瘦牛肉末93/7(生) | C7: 152 | D7: 21 | E7: 0 | F7: 7 | G7: 1 lb 装 | H7: 冷冻可 | I7: 是 | J7: 肥瘦比看包装
A8: 蛋白质 | B8: 牛腩(带肥,生) | C8: 250 | D8: 18 | E8: 0 | F8: 20 | G8: 按 lb | H8: 冷冻可 | I8: 是 | J8: 部位差异大;炖菜按生重记,油脂自动含
A9: 蛋白质 | B9: 牛腱(生) | C9: 150 | D9: 20 | E9: 0 | F9: 7 | G9: 按 lb | H9: 冷冻可 | I9: 是 | J9: 卤味用
A10: 蛋白质 | B10: 三文鱼(生) | C10: 208 | D10: 20 | E10: 0 | F10: 13 | G10: fillet/按 lb | H10: 冷冻可 | I10: 是
A11: 蛋白质 | B11: 虾(生,去壳) | C11: 85 | D11: 20 | E11: 0 | F11: 0.5 | G11: 冷冻 1-2 lb 袋 | H11: 冷冻可 | I11: 是
A12: 蛋白质 | B12: 白肉鱼(鲈/鳕,生) | C12: 90 | D12: 20 | E12: 0 | F12: 1 | G12: fillet | H12: 冷冻可 | I12: 是
A13: 蛋白质 | B13: 金枪鱼罐头(水浸) | C13: 127 | D13: 23.2 | E13: 0 | F13: 3.5 | G13: 5 oz 罐 | H13: 常温久放 | I13: 是 | J13: Wild Planet实测142g=180kcal/33P
A14: 蛋白质 | B14: 鸡蛋 | C14: 144 | D14: 12.6 | E14: 0.8 | F14: 9.6 | G14: 1打(12个) | H14: 冷藏数周 | I14: 是 | J14: 每个约50g(72kcal)
A15: 蛋白质 | B15: 老豆腐 firm tofu | C15: 80 | D15: 9 | E15: 2 | F15: 4.5 | G15: 14-16 oz 盒 | H15: 开封后2-3天 | I15: 否 | J15: 美国品牌差异大
A16: 蛋白质 | B16: 嫩豆腐 silken | C16: 55 | D16: 5 | E16: 2 | F16: 2.5 | G16: 14-16 oz 盒 | H16: 开封后2-3天 | I16: 否
A17: 蛋白质 | B17: 希腊酸奶(脱脂原味) | C17: 59 | D17: 10 | E17: 3.6 | F17: 0 | G17: 32 oz 桶/5.3 oz 杯 | H17: 冷藏 | I17: 是 | J17: 全脂/调味差异大
A18: 蛋白质 | B18: 豆浆(无糖) | C18: 38 | D18: 3.3 | E18: 1.2 | F18: 1.8 | G18: half gallon 盒 | H18: 冷藏久放 | I18: 是
A19: 蛋白质 | B19: 牛奶(2%) | C19: 50 | D19: 3.4 | E19: 4.8 | F19: 2 | G19: half gallon | H19: 冷藏~1周 | I19: 是 | J19: 量大易剩,考虑买小盒
A20: 碳水
A21: 碳水 | B21: 米饭(熟) | C21: 130 | D21: 2.7 | E21: 28 | F21: 0.3 | G21: 生米按 lb | H21: 熟饭冷藏 | I21: 是 | J21: 1拳≈150g≈195kcal
A22: 碳水 | B22: 糙米(熟) | C22: 123 | D22: 2.7 | E22: 26 | F22: 1 | G22: 袋装 | H22: 生米常温久 | I22: 是
A23: 碳水 | B23: 黑米(熟) | C23: 130 | D23: 3.5 | E23: 28 | F23: 1 | G23: 袋装 | H23: 生米常温久 | I23: 是
A24: 碳水 | B24: 红薯(熟) | C24: 90 | D24: 2 | E24: 21 | F24: 0.1 | G24: 按个/袋 | H24: 常温~1-2周 | I24: 半
A25: 碳水 | B25: 紫薯(熟) | C25: 90 | D25: 2 | E25: 21 | F25: 0.1 | G25: 按个/袋 | H25: 常温~1-2周 | I25: 半
A26: 碳水 | B26: 南瓜 kabocha(熟) | C26: 50 | D26: 1.8 | E26: 12 | F26: 0.1 | G26: 整个/半个 | H26: 整个常温久 | I26: 半 | J26: 品种差异大
A27: 碳水 | B27: 燕麦(干) | C27: 380 | D27: 13 | E27: 67 | F27: 7 | G27: 大桶 | H27: 常温久放 | I27: 是 | J27: 半拳干≈40g≈150kcal
A28: 碳水 | B28: 全麦面包 | C28: 268 | D28: 14 | E28: 46 | F28: 3.6 | G28: 1条(约20片) | H28: 冷藏~1周 | I28: 否 | J28: 每片约28g(75kcal)
A29: 碳水 | B29: 口袋面包 pita | C29: 275 | D29: 10 | E29: 55 | F29: 2.5 | G29: 袋装 | H29: 冷藏/冷冻 | I29: 半 | J29: 每个约60g
A30: 碳水 | B30: 乌冬(熟) | C30: 130 | D30: 3 | E30: 27 | F30: 0.5 | G30: 真空包 | H30: 冷藏 | I30: 是
A31: 碳水 | B31: 意面(干) | C31: 360 | D31: 13 | E31: 72 | F31: 1.5 | G31: 1 lb 盒 | H31: 常温久放 | I31: 是 | J31: 填干重
A32: 碳水 | B32: 玉米(煮) | C32: 96 | D32: 3.4 | E32: 21 | F32: 1.5 | G32: 按棒/袋 | H32: 冷藏 | I32: 半
A33: 脂肪
A34: 脂肪 | B34: 牛油果 | C34: 160 | D34: 2 | E34: 9 | F34: 15 | G34: 单个/袋 | H34: 熟后2-3天 | I34: 否 | J34: 半个≈100g
A35: 脂肪 | B35: 混合坚果 | C35: 600 | D35: 20 | E35: 20 | F35: 50 | G35: 袋/罐 | H35: 常温久放 | I35: 是 | J35: 贴纸<15g/次
A36: 脂肪 | B36: 橄榄油 | C36: 884 | D36: 0 | E36: 0 | F36: 100 | G36: 瓶装 | H36: 常温久放 | I36: 是 | J36: 1 tbsp≈14g≈120kcal
A37: 脂肪 | B37: 喷油(底油) | C37: 884 | D37: 0 | E37: 0 | F37: 100 | G37: 喷瓶 | H37: 常温久放 | I37: 是 | J37: 几喷≈可忽略,填2-5g
A38: 脂肪 | B38: 黑巧克力85% | C38: 600 | D38: 8 | E38: 30 | F38: 50 | G38: 块装 | H38: 常温久放 | I38: 是 | J38: 加餐小份
A39: 蔬菜（热量低，目测即可）
A40: 蔬菜 | B40: 西兰花 | C40: 34 | D40: 2.8 | E40: 7 | F40: 0.4 | G40: 整颗/袋 | H40: 冷藏~1周 | I40: 否
...

Sheet ②配方明细
A1: ② 配方明细 — 在「用量g」填克数，右侧自动联动食材库
A2: 配方名 | B2: 角色 | C2: 食材 | D2: 用量g | E2: 用量说明 | F2: 查:kcal/100 | G2: 查:P/100 | H2: 查:C/100 | I2: 查:F/100 | J2: 本项kcal | K2: 本项P | L2: 本项C | M2: 本项F
A3: 番茄炖牛腩 | B3: 蛋白主菜 | C3: 牛腩(带肥,生) | D3: 400 | E3: 约0.9 lb | F3: =IFERROR(VLOOKUP($C3,①食材库!$B:$F,2,FALSE()),0) -> 250 | G3: =IFERROR(VLOOKUP($C3,①食材库!$B:$F,3,FALSE()),0) -> 18 | H3: =IFERROR(VLOOKUP($C3,①食材库!$B:$F,4,FALSE()),0) -> 0 | I3: =IFERROR(VLOOKUP($C3,①食材库!$B:$F,5,FALSE()),0) -> 20 | J3: =ROUND($D3/100*F3,0) -> 1000 | K3: =ROUND($D3/100*G3,1) -> 72 | L3: =ROUND($D3/100*H3,1) -> 0 | M3: =ROUND($D3/100*I3,1) -> 80
A4: 番茄炖牛腩 | B4: 蛋白主菜 | C4: 番茄 | D4: 300 | E4: 约3个 | F4: =IFERROR(VLOOKUP($C4,①食材库!$B:$F,2,FALSE()),0) -> 18 | G4: =IFERROR(VLOOKUP($C4,①食材库!$B:$F,3,FALSE()),0) -> 0.9 | H4: =IFERROR(VLOOKUP($C4,①食材库!$B:$F,4,FALSE()),0) -> 3.9 | I4: =IFERROR(VLOOKUP($C4,①食材库!$B:$F,5,FALSE()),0) -> 0.2 | J4: =ROUND($D4/100*F4,0) -> 54 | K4: =ROUND($D4/100*G4,1) -> 2.7 | L4: =ROUND($D4/100*H4,1) -> 11.7 | M4: =ROUND($D4/100*I4,1) -> 0.6
A5: 番茄炖牛腩 | B5: 蛋白主菜 | C5: 洋葱 | D5: 80 | E5: 半个 | F5: =IFERROR(VLOOKUP($C5,①食材库!$B:$F,2,FALSE()),0) -> 40 | G5: =IFERROR(VLOOKUP($C5,①食材库!$B:$F,3,FALSE()),0) -> 1.1 | H5: =IFERROR(VLOOKUP($C5,①食材库!$B:$F,4,FALSE()),0) -> 9 | I5: =IFERROR(VLOOKUP($C5,①食材库!$B:$F,5,FALSE()),0) -> 0.1 | J5: =ROUND($D5/100*F5,0) -> 32 | K5: =ROUND($D5/100*G5,1) -> 0.9 | L5: =ROUND($D5/100*H5,1) -> 7.2 | M5: =ROUND($D5/100*I5,1) -> 0.1
A6: 番茄炖牛腩 | B6: 蛋白主菜 | C6: 喷油(底油) | D6: 3 | E6: 几喷 | F6: =IFERROR(VLOOKUP($C6,①食材库!$B:$F,2,FALSE()),0) -> 884 | G6: =IFERROR(VLOOKUP($C6,①食材库!$B:$F,3,FALSE()),0) -> 0 | H6: =IFERROR(VLOOKUP($C6,①食材库!$B:$F,4,FALSE()),0) -> 0 | I6: =IFERROR(VLOOKUP($C6,①食材库!$B:$F,5,FALSE()),0) -> 100 | J6: =ROUND($D6/100*F6,0) -> 27 | K6: =ROUND($D6/100*G6,1) -> 0 | L6: =ROUND($D6/100*H6,1) -> 0 | M6: =ROUND($D6/100*I6,1) -> 3
A7: 咖喱鸡 | B7: 蛋白主菜 | C7: 鸡腿肉去皮(生) | D7: 400 | F7: =IFERROR(VLOOKUP($C7,①食材库!$B:$F,2,FALSE()),0) -> 120 | G7: =IFERROR(VLOOKUP($C7,①食材库!$B:$F,3,FALSE()),0) -> 20 | H7: =IFERROR(VLOOKUP($C7,①食材库!$B:$F,4,FALSE()),0) -> 0 | I7: =IFERROR(VLOOKUP($C7,①食材库!$B:$F,5,FALSE()),0) -> 4 | J7: =ROUND($D7/100*F7,0) -> 480 | K7: =ROUND($D7/100*G7,1) -> 80 | L7: =ROUND($D7/100*H7,1) -> 0 | M7: =ROUND($D7/100*I7,1) -> 16
A8: 咖喱鸡 | B8: 蛋白主菜 | C8: 咖喱块 | D8: 60 | E8: 约3块 | F8: =IFERROR(VLOOKUP($C8,①食材库!$B:$F,2,FALSE()),0) -> 450 | G8: =IFERROR(VLOOKUP($C8,①食材库!$B:$F,3,FALSE()),0) -> 6 | H8: =IFERROR(VLOOKUP($C8,①食材库!$B:$F,4,FALSE()),0) -> 45 | I8: =IFERROR(VLOOKUP($C8,①食材库!$B:$F,5,FALSE()),0) -> 28 | J8: =ROUND($D8/100*F8,0) -> 270 | K8: =ROUND($D8/100*G8,1) -> 3.6 | L8: =ROUND($D8/100*H8,1) -> 27 | M8: =ROUND($D8/100*I8,1) -> 16.8
A9: 咖喱鸡 | B9: 蛋白主菜 | C9: 洋葱 | D9: 100 | F9: =IFERROR(VLOOKUP($C9,①食材库!$B:$F,2,FALSE()),0) -> 40 | G9: =IFERROR(VLOOKUP($C9,①食材库!$B:$F,3,FALSE()),0) -> 1.1 | H9: =IFERROR(VLOOKUP($C9,①食材库!$B:$F,4,FALSE()),0) -> 9 | I9: =IFERROR(VLOOKUP($C9,①食材库!$B:$F,5,FALSE()),0) -> 0.1 | J9: =ROUND($D9/100*F9,0) -> 40 | K9: =ROUND($D9/100*G9,1) -> 1.1 | L9: =ROUND($D9/100*H9,1) -> 9 | M9: =ROUND($D9/100*I9,1) -> 0.1
A10: 咖喱鸡 | B10: 蛋白主菜 | C10: 胡萝卜 | D10: 100 | F10: =IFERROR(VLOOKUP($C10,①食材库!$B:$F,2,FALSE()),0) -> 41 | G10: =IFERROR(VLOOKUP($C10,①食材库!$B:$F,3,FALSE()),0) -> 0.9 | H10: =IFERROR(VLOOKUP($C10,①食材库!$B:$F,4,FALSE()),0) -> 10 | I10: =IFERROR(VLOOKUP($C10,①食材库!$B:$F,5,FALSE()),0) -> 0.2 | J10: =ROUND($D10/100*F10,0) -> 41 | K10: =ROUND($D10/100*G10,1) -> 0.9 | L10: =ROUND($D10/100*H10,1) -> 10 | M10: =ROUND($D10/100*I10,1) -> 0.2
A11: 香煎鸡胸 | B11: 蛋白主菜 | C11: 鸡胸肉(生) | D11: 200 | F11: =IFERROR(VLOOKUP($C11,①食材库!$B:$F,2,FALSE()),0) -> 120 | G11: =IFERROR(VLOOKUP($C11,①食材库!$B:$F,3,FALSE()),0) -> 23 | H11: =IFERROR(VLOOKUP($C11,①食材库!$B:$F,4,FALSE()),0) -> 0 | I11: =IFERROR(VLOOKUP($C11,①食材库!$B:$F,5,FALSE()),0) -> 2.6 | J11: =ROUND($D11/100*F11,0) -> 240 | K11: =ROUND($D11/100*G11,1) -> 46 | L11: =ROUND($D11/100*H11,1) -> 0 | M11: =ROUND($D11/100*I11,1) -> 5.2
A12: 香煎鸡胸 | B12: 蛋白主菜 | C12: 喷油(底油) | D12: 3 | E12: 几喷 | F12: =IFERROR(VLOOKUP($C12,①食材库!$B:$F,2,FALSE()),0) -> 884 | G12: =IFERROR(VLOOKUP($C12,①食材库!$B:$F,3,FALSE()),0) -> 0 | H12: =IFERROR(VLOOKUP($C12,①食材库!$B:$F,4,FALSE()),0) -> 0 | I12: =IFERROR(VLOOKUP($C12,①食材库!$B:$F,5,FALSE()),0) -> 100 | J12: =ROUND($D12/100*F12,0) -> 27 | K12: =ROUND($D12/100*G12,1) -> 0 | L12: =ROUND($D12/100*H12,1) -> 0 | M12: =ROUND($D12/100*I12,1) -> 3
A13: 白灼大虾 | B13: 蛋白主菜 | C13: 虾(生,去壳) | D13: 200 | F13: =IFERROR(VLOOKUP($C13,①食材库!$B:$F,2,FALSE()),0) -> 85 | G13: =IFERROR(VLOOKUP($C13,①食材库!$B:$F,3,FALSE()),0) -> 20 | H13: =IFERROR(VLOOKUP($C13,①食材库!$B:$F,4,FALSE()),0) -> 0 | I13: =IFERROR(VLOOKUP($C13,①食材库!$B:$F,5,FALSE()),0) -> 0.5 | J13: =ROUND($D13/100*F13,0) -> 170 | K13: =ROUND($D13/100*G13,1) -> 40 | L13: =ROUND($D13/100*H13,1) -> 0 | M13: =ROUND($D13/100*I13,1) -> 1
A14: 清蒸鲈鱼 | B14: 蛋白主菜 | C14: 白肉鱼(鲈/鳕,生) | D14: 250 | F14: =IFERROR(VLOOKUP($C14,①食材库!$B:$F,2,FALSE()),0) -> 90 | G14: =IFERROR(VLOOKUP($C14,①食材库!$B:$F,3,FALSE()),0) -> 20 | H14: =IFERROR(VLOOKUP($C14,①食材库!$B:$F,4,FALSE()),0) -> 0 | I14: =IFERROR(VLOOKUP($C14,①食材库!$B:$F,5,FALSE()),0) -> 1 | J14: =ROUND($D14/100*F14,0) -> 225 | K14: =ROUND($D14/100*G14,1) -> 50 | L14: =ROUND($D14/100*H14,1) -> 0 | M14: =ROUND($D14/100*I14,1) -> 2.5
A15: 豆芽炒牛肉 | B15: 蛋白主菜 | C15: 瘦牛肉末93/7(生) | D15: 150 | F15: =IFERROR(VLOOKUP($C15,①食材库!$B:$F,2,FALSE()),0) -> 152 | G15: =IFERROR(VLOOKUP($C15,①食材库!$B:$F,3,FALSE()),0) -> 21 | H15: =IFERROR(VLOOKUP($C15,①食材库!$B:$F,4,FALSE()),0) -> 0 | I15: =IFERROR(VLOOKUP($C15,①食材库!$B:$F,5,FALSE()),0) -> 7 | J15: =ROUND($D15/100*F15,0) -> 228 | K15: =ROUND($D15/100*G15,1) -> 31.5 | L15: =ROUND($D15/100*H15,1) -> 0 | M15: =ROUND($D15/100*I15,1) -> 10.5
A16: 豆芽炒牛肉 | B16: 蛋白主菜 | C16: 绿豆芽 | D16: 150 | F16: =IFERROR(VLOOKUP($C16,①食材库!$B:$F,2,FALSE()),0) -> 30 | G16: =IFERROR(VLOOKUP($C16,①食材库!$B:$F,3,FALSE()),0) -> 3 | H16: =IFERROR(VLOOKUP($C16,①食材库!$B:$F,4,FALSE()),0) -> 6 | I16: =IFERROR(VLOOKUP($C16,①食材库!$B:$F,5,FALSE()),0) -> 0.2 | J16: =ROUND($D16/100*F16,0) -> 45 | K16: =ROUND($D16/100*G16,1) -> 4.5 | L16: =ROUND($D16/100*H16,1) -> 9 | M16: =ROUND($D16/100*I16,1) -> 0.3
A17: 豆芽炒牛肉 | B17: 蛋白主菜 | C17: 喷油(底油) | D17: 3 | F17: =IFERROR(VLOOKUP($C17,①食材库!$B:$F,2,FALSE()),0) -> 884 | G17: =IFERROR(VLOOKUP($C17,①食材库!$B:$F,3,FALSE()),0) -> 0 | H17: =IFERROR(VLOOKUP($C17,①食材库!$B:$F,4,FALSE()),0) -> 0 | I17: =IFERROR(VLOOKUP($C17,①食材库!$B:$F,5,FALSE()),0) -> 100 | J17: =ROUND($D17/100*F17,0) -> 27 | K17: =ROUND($D17/100*G17,1) -> 0 | L17: =ROUND($D17/100*H17,1) -> 0 | M17: =ROUND($D17/100*I17,1) -> 3
A18: 番茄炒蛋 | B18: 蛋白主菜 | C18: 鸡蛋 | D18: 150 | E18: 3个 | F18: =IFERROR(VLOOKUP($C18,①食材库!$B:$F,2,FALSE()),0) -> 144 | G18: =IFERROR(VLOOKUP($C18,①食材库!$B:$F,3,FALSE()),0) -> 12.6 | H18: =IFERROR(VLOOKUP($C18,①食材库!$B:$F,4,FALSE()),0) -> 0.8 | I18: =IFERROR(VLOOKUP($C18,①食材库!$B:$F,5,FALSE()),0) -> 9.6 | J18: =ROUND($D18/100*F18,0) -> 216 | K18: =ROUND($D18/100*G18,1) -> 18.9 | L18: =ROUND($D18/100*H18,1) -> 1.2 | M18: =ROUND($D18/100*I18,1) -> 14.4
A19: 番茄炒蛋 | B19: 蛋白主菜 | C19: 番茄 | D19: 200 | F19: =IFERROR(VLOOKUP($C19,①食材库!$B:$F,2,FALSE()),0) -> 18 | G19: =IFERROR(VLOOKUP($C19,①食材库!$B:$F,3,FALSE()),0) -> 0.9 | H19: =IFERROR(VLOOKUP($C19,①食材库!$B:$F,4,FALSE()),0) -> 3.9 | I19: =IFERROR(VLOOKUP($C19,①食材库!$B:$F,5,FALSE()),0) -> 0.2 | J19: =ROUND($D19/100*F19,0) -> 36 | K19: =ROUND($D19/100*G19,1) -> 1.8 | L19: =ROUND($D19/100*H19,1) -> 7.8 | M19: =ROUND($D19/100*I19,1) -> 0.4
A20: 番茄炒蛋 | B20: 蛋白主菜 | C20: 喷油(底油) | D20: 3 | F20: =IFERROR(VLOOKUP($C20,①食材库!$B:$F,2,FALSE()),0) -> 884 | G20: =IFERROR(VLOOKUP($C20,①食材库!$B:$F,3,FALSE()),0) -> 0 | H20: =IFERROR(VLOOKUP($C20,①食材库!$B:$F,4,FALSE()),0) -> 0 | I20: =IFERROR(VLOOKUP($C20,①食材库!$B:$F,5,FALSE()),0) -> 100 | J20: =ROUND($D20/100*F20,0) -> 27 | K20: =ROUND($D20/100*G20,1) -> 0 | L20: =ROUND($D20/100*H20,1) -> 0 | M20: =ROUND($D20/100*I20,1) -> 3
A21: 卤牛腱 | B21: 蛋白主菜 | C21: 牛腱(生) | D21: 300 | F21: =IFERROR(VLOOKUP($C21,①食材库!$B:$F,2,FALSE()),0) -> 150 | G21: =IFERROR(VLOOKUP($C21,①食材库!$B:$F,3,FALSE()),0) -> 20 | H21: =IFERROR(VLOOKUP($C21,①食材库!$B:$F,4,FALSE()),0) -> 0 | I21: =IFERROR(VLOOKUP($C21,①食材库!$B:$F,5,FALSE()),0) -> 7 | J21: =ROUND($D21/100*F21,0) -> 450 | K21: =ROUND($D21/100*G21,1) -> 60 | L21: =ROUND($D21/100*H21,1) -> 0 | M21: =ROUND($D21/100*I21,1) -> 21
A22: 香煎三文鱼 | B22: 蛋白主菜 | C22: 三文鱼(生) | D22: 200 | F22: =IFERROR(VLOOKUP($C22,①食材库!$B:$F,2,FALSE()),0) -> 208 | G22: =IFERROR(VLOOKUP($C22,①食材库!$B:$F,3,FALSE()),0) -> 20 | H22: =IFERROR(VLOOKUP($C22,①食材库!$B:$F,4,FALSE()),0) -> 0 | I22: =IFERROR(VLOOKUP($C22,①食材库!$B:$F,5,FALSE()),0) -> 13 | J22: =ROUND($D22/100*F22,0) -> 416 | K22: =ROUND($D22/100*G22,1) -> 40 | L22: =ROUND($D22/100*H22,1) -> 0 | M22: =ROUND($D22/100*I22,1) -> 26
A23: 香煎三文鱼 | B23: 蛋白主菜 | C23: 喷油(底油) | D23: 3 | F23: =IFERROR(VLOOKUP($C23,①食材库!$B:$F,2,FALSE()),0) -> 884 | G23: =IFERROR(VLOOKUP($C23,①食材库!$B:$F,3,FALSE()),0) -> 0 | H23: =IFERROR(VLOOKUP($C23,①食材库!$B:$F,4,FALSE()),0) -> 0 | I23: =IFERROR(VLOOKUP($C23,①食材库!$B:$F,5,FALSE()),0) -> 100 | J23: =ROUND($D23/100*F23,0) -> 27 | K23: =ROUND($D23/100*G23,1) -> 0 | L23: =ROUND($D23/100*H23,1) -> 0 | M23: =ROUND($D23/100*I23,1) -> 3
A24: 彩椒炒鸡胸 | B24: 蛋白主菜 | C24: 鸡胸肉(生) | D24: 200 | F24: =IFERROR(VLOOKUP($C24,①食材库!$B:$F,2,FALSE()),0) -> 120 | G24: =IFERROR(VLOOKUP($C24,①食材库!$B:$F,3,FALSE()),0) -> 23 | H24: =IFERROR(VLOOKUP($C24,①食材库!$B:$F,4,FALSE()),0) -> 0 | I24: =IFERROR(VLOOKUP($C24,①食材库!$B:$F,5,FALSE()),0) -> 2.6 | J24: =ROUND($D24/100*F24,0) -> 240 | K24: =ROUND($D24/100*G24,1) -> 46 | L24: =ROUND($D24/100*H24,1) -> 0 | M24: =ROUND($D24/100*I24,1) -> 5.2
A25: 彩椒炒鸡胸 | B25: 蛋白主菜 | C25: 彩椒 | D25: 150 | F25: =IFERROR(VLOOKUP($C25,①食材库!$B:$F,2,FALSE()),0) -> 31 | G25: =IFERROR(VLOOKUP($C25,①食材库!$B:$F,3,FALSE()),0) -> 1 | H25: =IFERROR(VLOOKUP($C25,①食材库!$B:$F,4,FALSE()),0) -> 6 | I25: =IFERROR(VLOOKUP($C25,①食材库!$B:$F,5,FALSE()),0) -> 0.3 | J25: =ROUND($D25/100*F25,0) -> 47 | K25: =ROUND($D25/100*G25,1) -> 1.5 | L25: =ROUND($D25/100*H25,1) -> 9 | M25: =ROUND($D25/100*I25,1) -> 0.5
A26: 彩椒炒鸡胸 | B26: 蛋白主菜 | C26: 喷油(底油) | D26: 3 | F26: =IFERROR(VLOOKUP($C26,①食材库!$B:$F,2,FALSE()),0) -> 884 | G26: =IFERROR(VLOOKUP($C26,①食材库!$B:$F,3,FALSE()),0) -> 0 | H26: =IFERROR(VLOOKUP($C26,①食材库!$B:$F,4,FALSE()),0) -> 0 | I26: =IFERROR(VLOOKUP($C26,①食材库!$B:$F,5,FALSE()),0) -> 100 | J26: =ROUND($D26/100*F26,0) -> 27 | K26: =ROUND($D26/100*G26,1) -> 0 | L26: =ROUND($D26/100*H26,1) -> 0 | M26: =ROUND($D26/100*I26,1) -> 3
A27: 蒜蓉西兰花 | B27: 蔬菜 | C27: 西兰花 | D27: 250 | F27: =IFERROR(VLOOKUP($C27,①食材库!$B:$F,2,FALSE()),0) -> 34 | G27: =IFERROR(VLOOKUP($C27,①食材库!$B:$F,3,FALSE()),0) -> 2.8 | H27: =IFERROR(VLOOKUP($C27,①食材库!$B:$F,4,FALSE()),0) -> 7 | I27: =IFERROR(VLOOKUP($C27,①食材库!$B:$F,5,FALSE()),0) -> 0.4 | J27: =ROUND($D27/100*F27,0) -> 85 | K27: =ROUND($D27/100*G27,1) -> 7 | L27: =ROUND($D27/100*H27,1) -> 17.5 | M27: =ROUND($D27/100*I27,1) -> 1
A28: 蒜蓉西兰花 | B28: 蔬菜 | C28: 喷油(底油) | D28: 3 | F28: =IFERROR(VLOOKUP($C28,①食材库!$B:$F,2,FALSE()),0) -> 884 | G28: =IFERROR(VLOOKUP($C28,①食材库!$B:$F,3,FALSE()),0) -> 0 | H28: =IFERROR(VLOOKUP($C28,①食材库!$B:$F,4,FALSE()),0) -> 0 | I28: =IFERROR(VLOOKUP($C28,①食材库!$B:$F,5,FALSE()),0) -> 100 | J28: =ROUND($D28/100*F28,0) -> 27 | K28: =ROUND($D28/100*G28,1) -> 0 | L28: =ROUND($D28/100*H28,1) -> 0 | M28: =ROUND($D28/100*I28,1) -> 3
A29: 清炒菠菜 | B29: 蔬菜 | C29: 菠菜 | D29: 200 | F29: =IFERROR(VLOOKUP($C29,①食材库!$B:$F,2,FALSE()),0) -> 23 | G29: =IFERROR(VLOOKUP($C29,①食材库!$B:$F,3,FALSE()),0) -> 2.9 | H29: =IFERROR(VLOOKUP($C29,①食材库!$B:$F,4,FALSE()),0) -> 3.6 | I29: =IFERROR(VLOOKUP($C29,①食材库!$B:$F,5,FALSE()),0) -> 0.4 | J29: =ROUND($D29/100*F29,0) -> 46 | K29: =ROUND($D29/100*G29,1) -> 5.8 | L29: =ROUND($D29/100*H29,1) -> 7.2 | M29: =ROUND($D29/100*I29,1) -> 0.8
A30: 清炒菠菜 | B30: 蔬菜 | C30: 喷油(底油) | D30: 3 | F30: =IFERROR(VLOOKUP($C30,①食材库!$B:$F,2,FALSE()),0) -> 884 | G30: =IFERROR(VLOOKUP($C30,①食材库!$B:$F,3,FALSE()),0) -> 0 | H30: =IFERROR(VLOOKUP($C30,①食材库!$B:$F,4,FALSE()),0) -> 0 | I30: =IFERROR(VLOOKUP($C30,①食材库!$B:$F,5,FALSE()),0) -> 100 | J30: =ROUND($D30/100*F30,0) -> 27 | K30: =ROUND($D30/100*G30,1) -> 0 | L30: =ROUND($D30/100*H30,1) -> 0 | M30: =ROUND($D30/100*I30,1) -> 3
... A44: 番茄豆芽汤 | B44: 汤 | C44: 绿豆芽 | D44: 100 | F44: =IFERROR(VLOOKUP($C44,①食材库!$B:$F,2,FALSE()),0) -> 30 | G44: =IFERROR(VLOOKUP($C44,①食材库!$B:$F,3,FALSE()),0) -> 3 | H44: =IFERROR(VLOOKUP($C44,①食材库!$B:$F,4,FALSE()),0) -> 6 | I44: =IFERROR(VLOOKUP($C44,①食材库!$B:$F,5,FALSE()),0) -> 0.2 | J44: =ROUND($D44/100*F44,0) -> 30 | K44: =ROUND($D44/100*G44,1) -> 3 | L44: =ROUND($D44/100*H44,1) -> 6 | M44: =ROUND($D44/100*I44,1) -> 0.2
A45: 番茄豆芽汤 | B45: 汤 | C45: 鸡蛋 | D45: 50 | E45: 1个 | F45: =IFERROR(VLOOKUP($C45,①食材库!$B:$F,2,FALSE()),0) -> 144 | G45: =IFERROR(VLOOKUP($C45,①食材库!$B:$F,3,FALSE()),0) -> 12.6 | H45: =IFERROR(VLOOKUP($C45,①食材库!$B:$F,4,FALSE()),0) -> 0.8 | I45: =IFERROR(VLOOKUP($C45,①食材库!$B:$F,5,FALSE()),0) -> 9.6 | J45: =ROUND($D45/100*F45,0) -> 72 | K45: =ROUND($D45/100*G45,1) -> 6.3 | L45: =ROUND($D45/100*H45,1) -> 0.4 | M45: =ROUND($D45/100*I45,1) -> 4.8
A46: 萝卜牛肉汤 | B46: 汤 | C46: 瘦牛肉末93/7(生) | D46: 300 | F46: =IFERROR(VLOOKUP($C46,①食材库!$B:$F,2,FALSE()),0) -> 152 | G46: =IFERROR(VLOOKUP($C46,①食材库!$B:$F,3,FALSE()),0) -> 21 | H46: =IFERROR(VLOOKUP($C46,①食材库!$B:$F,4,FALSE()),0) -> 0 | I46: =IFERROR(VLOOKUP($C46,①食材库!$B:$F,5,FALSE()),0) -> 7 | J46: =ROUND($D46/100*F46,0) -> 456 | K46: =ROUND($D46/100*G46,1) -> 63 | L46: =ROUND($D46/100*H46,1) -> 0 | M46: =ROUND($D46/100*I46,1) -> 21
A47: 萝卜牛肉汤 | B47: 汤 | C47: 白萝卜 | D47: 300 | F47: =IFERROR(VLOOKUP($C47,①食材库!$B:$F,2,FALSE()),0) -> 18 | G47: =IFERROR(VLOOKUP($C47,①食材库!$B:$F,3,FALSE()),0) -> 0.6 | H47: =IFERROR(VLOOKUP($C47,①食材库!$B:$F,4,FALSE()),0) -> 4 | I47: =IFERROR(VLOOKUP($C47,①食材库!$B:$F,5,FALSE()),0) -> 0.1 | J47: =ROUND($D47/100*F47,0) -> 54 | K47: =ROUND($D47/100*G47,1) -> 1.8 | L47: =ROUND($D47/100*H47,1) -> 12 | M47: =ROUND($D47/100*I47,1) -> 0.3
A48: 辣牛肉豆腐汤 | B48: 汤 | C48: 瘦牛肉末93/7(生) | D48: 200 | F48: =IFERROR(VLOOKUP($C48,①食材库!$B:$F,2,FALSE()),0) -> 152 | G48: =IFERROR(VLOOKUP($C48,①食材库!$B:$F,3,FALSE()),0) -> 21 | H48: =IFERROR(VLOOKUP($C48,①食材库!$B:$F,4,FALSE()),0) -> 0 | I48: =IFERROR(VLOOKUP($C48,①食材库!$B:$F,5,FALSE()),0) -> 7 | J48: =ROUND($D48/100*F48,0) -> 304 | K48: =ROUND($D48/100*G48,1) -> 42 | L48: =ROUND($D48/100*H48,1) -> 0 | M48: =ROUND($D48/100*I48,1) -> 14
A49: 辣牛肉豆腐汤 | B49: 汤 | C49: 老豆腐 firm tofu | D49: 200 | F49: =IFERROR(VLOOKUP($C49,①食材库!$B:$F,2,FALSE()),0) -> 80 | G49: =IFERROR(VLOOKUP($C49,①食材库!$B:$F,3,FALSE()),0) -> 9 | H49: =IFERROR(VLOOKUP($C49,①食材库!$B:$F,4,FALSE()),0) -> 2 | I49: =IFERROR(VLOOKUP($C49,①食材库!$B:$F,5,FALSE()),0) -> 4.5 | J49: =ROUND($D49/100*F49,0) -> 160 | K49: =ROUND($D49/100*G49,1) -> 18 | L49: =ROUND($D49/100*H49,1) -> 4 | M49: =ROUND($D49/100*I49,1) -> 9
A50: 辣牛肉豆腐汤 | B50: 汤 | C50: 辣白菜 kimchi | D50: 100 | F50: =IFERROR(VLOOKUP($C50,①食材库!$B:$F,2,FALSE()),0) -> 30 | G50: =IFERROR(VLOOKUP($C50,①食材库!$B:$F,3,FALSE()),0) -> 1.6 | H50: =IFERROR(VLOOKUP($C50,①食材库!$B:$F,4,FALSE()),0) -> 6 | I50: =IFERROR(VLOOKUP($C50,①食材库!$B:$F,5,FALSE()),0) -> 0.5 | J50: =ROUND($D50/100*F50,0) -> 30 | K50: =ROUND($D50/100*G50,1) -> 1.6 | L50: =ROUND($D50/100*H50,1) -> 6 | M50: =ROUND($D50/100*I50,1) -> 0.5
A51: 白米饭 | B51: 主食 | C51: 米饭(熟) | D51: 300 | E51: 约2拳 | F51: =IFERROR(VLOOKUP($C51,①食材库!$B:$F,2,FALSE()),0) -> 130 | G51: =IFERROR(VLOOKUP($C51,①食材库!$B:$F,3,FALSE()),0) -> 2.7 | H51: =IFERROR(VLOOKUP($C51,①食材库!$B:$F,4,FALSE()),0) -> 28 | I51: =IFERROR(VLOOKUP($C51,①食材库!$B:$F,5,FALSE()),0) -> 0.3 | J51: =ROUND($D51/100*F51,0) -> 390 | K51: =ROUND($D51/100*G51,1) -> 8.1 | L51: =ROUND($D51/100*H51,1) -> 84 | M51: =ROUND($D51/100*I51,1) -> 0.9
A52: 蒸红薯 | B52: 主食 | C52: 红薯(熟) | D52: 250 | F52: =IFERROR(VLOOKUP($C52,①食材库!$B:$F,2,FALSE()),0) -> 90 | G52: =IFERROR(VLOOKUP($C52,①食材库!$B:$F,3,FALSE()),0) -> 2 | H52: =IFERROR(VLOOKUP($C52,①食材库!$B:$F,4,FALSE()),0) -> 21 | I52: =IFERROR(VLOOKUP($C52,①食材库!$B:$F,5,FALSE()),0) -> 0.1 | J52: =ROUND($D52/100*F52,0) -> 225 | K52: =ROUND($D52/100*G52,1) -> 5 | L52: =ROUND($D52/100*H52,1) -> 52.5 | M52: =ROUND($D52/100*I52,1) -> 0.3
A53: 燕麦粥 | B53: 主食 | C53: 燕麦(干) | D53: 40 | E53: 半拳 | F53: =IFERROR(VLOOKUP($C53,①食材库!$B:$F,2,FALSE()),0) -> 380 | G53: =IFERROR(VLOOKUP($C53,①食材库!$B:$F,3,FALSE()),0) -> 13 | H53: =IFERROR(VLOOKUP($C53,①食材库!$B:$F,4,FALSE()),0) -> 67 | I53: =IFERROR(VLOOKUP($C53,①食材库!$B:$F,5,FALSE()),0) -> 7 | J53: =ROUND($D53/100*F53,0) -> 152 | K53: =ROUND($D53/100*G53,1) -> 5.2 | L53: =ROUND($D53/100*H53,1) -> 26.8 | M53: =ROUND($D53/100*I53,1) -> 2.8
...

Sheet ③配方汇总
A1: ③ 配方汇总 — 整批=明细自动加总(生重相加)，每份=整批÷份数
A2: 配方名 | B2: 角色 | C2: 典型份数 | D2: 整批kcal | E2: 整批P | F2: 整批C | G2: 整批F | H2: 每份kcal | I2: 每份P | J2: 每份C | K2: 每份F | L2: 备注
A3: 蛋白主菜
A4: 番茄炖牛腩 | B4: 蛋白主菜 | C4: 4 | D4: =SUMIF(②配方明细!$A:$A,$A4,②配方明细!$J:$J) -> 1113 | E4: =ROUND(SUMIF(②配方明细!$A:$A,$A4,②配方明细!$K:$K),1) -> 75.6 | F4: =ROUND(SUMIF(②配方明细!$A:$A,$A4,②配方明细!$L:$L),1) -> 18.9 | G4: =ROUND(SUMIF(②配方明细!$A:$A,$A4,②配方明细!$M:$M),1) -> 83.7 | H4: =IFERROR(ROUND(D4/C4,0),0) -> 278 | I4: =IFERROR(ROUND(E4/C4,1),0) -> 18.9 | J4: =IFERROR(ROUND(F4/C4,1),0) -> 4.7 | K4: =IFERROR(ROUND(G4/C4,1),0) -> 20.9 | L4: 你常做,按实际牛腩量改份数
A5: 咖喱鸡 | B5: 蛋白主菜 | C5: 4 | D5: =SUMIF(②配方明细!$A:$A,$A5,②配方明细!$J:$J) -> 831 | E5: =ROUND(SUMIF(②配方明细!$A:$A,$A5,②配方明细!$K:$K),1) -> 85.6 | F5: =ROUND(SUMIF(②配方明细!$A:$A,$A5,②配方明细!$L:$L),1) -> 46 | G5: =ROUND(SUMIF(②配方明细!$A:$A,$A5,②配方明细!$M:$M),1) -> 33.1 | H5: =IFERROR(ROUND(D5/C5,0),0) -> 208 | I5: =IFERROR(ROUND(E5/C5,1),0) -> 21.4 | J5: =IFERROR(ROUND(F5/C5,1),0) -> 11.5 | K5: =IFERROR(ROUND(G5/C5,1),0) -> 8.3 | L5: 咖喱块务必核热量
A6: 香煎鸡胸 | B6: 蛋白主菜 | C6: 1 | D6: =SUMIF(②配方明细!$A:$A,$A6,②配方明细!$J:$J) -> 267 | E6: =ROUND(SUMIF(②配方明细!$A:$A,$A6,②配方明细!$K:$K),1) -> 46 | F6: =ROUND(SUMIF(②配方明细!$A:$A,$A6,②配方明细!$L:$L),1) -> 0 | G6: =ROUND(SUMIF(②配方明细!$A:$A,$A6,②配方明细!$M:$M),1) -> 8.2 | H6: =IFERROR(ROUND(D6/C6,0),0) -> 267 | I6: =IFERROR(ROUND(E6/C6,1),0) -> 46 | J6: =IFERROR(ROUND(F6/C6,1),0) -> 0 | K6: =IFERROR(ROUND(G6/C6,1),0) -> 8.2
A7: 白灼大虾 | B7: 蛋白主菜 | C7: 1 | D7: =SUMIF(②配方明细!$A:$A,$A7,②配方明细!$J:$J) -> 170 | E7: =ROUND(SUMIF(②配方明细!$A:$A,$A7,②配方明细!$K:$K),1) -> 40 | F7: =ROUND(SUMIF(②配方明细!$A:$A,$A7,②配方明细!$L:$L),1) -> 0 | G7: =ROUND(SUMIF(②配方明细!$A:$A,$A7,②配方明细!$M:$M),1) -> 1 | H7: =IFERROR(ROUND(D7/C7,0),0) -> 170 | I7: =IFERROR(ROUND(E7/C7,1),0) -> 40 | J7: =IFERROR(ROUND(F7/C7,1),0) -> 0 | K7: =IFERROR(ROUND(G7/C7,1),0) -> 1
A8: 清蒸鲈鱼 | B8: 蛋白主菜 | C8: 1 | D8: =SUMIF(②配方明细!$A:$A,$A8,②配方明细!$J:$J) -> 225 | E8: =ROUND(SUMIF(②配方明细!$A:$A,$A8,②配方明细!$K:$K),1) -> 50 | F8: =ROUND(SUMIF(②配方明细!$A:$A,$A8,②配方明细!$L:$L),1) -> 0 | G8: =ROUND(SUMIF(②配方明细!$A:$A,$A8,②配方明细!$M:$M),1) -> 2.5 | H8: =IFERROR(ROUND(D8/C8,0),0) -> 225 | I8: =IFERROR(ROUND(E8/C8,1),0) -> 50 | J8: =IFERROR(ROUND(F8/C8,1),0) -> 0 | K8: =IFERROR(ROUND(G8/C8,1),0) -> 2.5
A9: 豆芽炒牛肉 | B9: 蛋白主菜 | C9: 1 | D9: =SUMIF(②配方明细!$A:$A,$A9,②配方明细!$J:$J) -> 300 | E9: =ROUND(SUMIF(②配方明细!$A:$A,$A9,②配方明细!$K:$K),1) -> 36 | F9: =ROUND(SUMIF(②配方明细!$A:$A,$A9,②配方明细!$L:$L),1) -> 9 | G9: =ROUND(SUMIF(②配方明细!$A:$A,$A9,②配方明细!$M:$M),1) -> 13.8 | H9: =IFERROR(ROUND(D9/C9,0),0) -> 300 | I9: =IFERROR(ROUND(E9/C9,1),0) -> 36 | J9: =IFERROR(ROUND(F9/C9,1),0) -> 9 | K9: =IFERROR(ROUND(G9/C9,1),0) -> 13.8
A10: 番茄炒蛋 | B10: 蛋白主菜 | C10: 2 | D10: =SUMIF(②配方明细!$A:$A,$A10,②配方明细!$J:$J) -> 279 | E10: =ROUND(SUMIF(②配方明细!$A:$A,$A10,②配方明细!$K:$K),1) -> 20.7 | F10: =ROUND(SUMIF(②配方明细!$A:$A,$A10,②配方明细!$L:$L),1) -> 9 | G10: =ROUND(SUMIF(②配方明细!$A:$A,$A10,②配方明细!$M:$M),1) -> 17.8 | H10: =IFERROR(ROUND(D10/C10,0),0) -> 140 | I10: =IFERROR(ROUND(E10/C10,1),0) -> 10.4 | J10: =IFERROR(ROUND(F10/C10,1),0) -> 4.5 | K10: =IFERROR(ROUND(G10/C10,1),0) -> 8.9
A11: 卤牛腱 | B11: 蛋白主菜 | C11: 3 | D11: =SUMIF(②配方明细!$A:$A,$A11,②配方明细!$J:$J) -> 450 | E11: =ROUND(SUMIF(②配方明细!$A:$A,$A11,②配方明细!$K:$K),1) -> 60 | F11: =ROUND(SUMIF(②配方明细!$A:$A,$A11,②配方明细!$L:$L),1) -> 0 | G11: =ROUND(SUMIF(②配方明细!$A:$A,$A11,②配方明细!$M:$M),1) -> 21 | H11: =IFERROR(ROUND(D11/C11,0),0) -> 150 | I11: =IFERROR(ROUND(E11/C11,1),0) -> 20 | J11: =IFERROR(ROUND(F11/C11,1),0) -> 0 | K11: =IFERROR(ROUND(G11/C11,1),0) -> 7 | L11: 做一批分几顿
A12: 香煎三文鱼 | B12: 蛋白主菜 | C12: 1 | D12: =SUMIF(②配方明细!$A:$A,$A12,②配方明细!$J:$J) -> 443 | E12: =ROUND(SUMIF(②配方明细!$A:$A,$A12,②配方明细!$K:$K),1) -> 40 | F12: =ROUND(SUMIF(②配方明细!$A:$A,$A12,②配方明细!$L:$L),1) -> 0 | G12: =ROUND(SUMIF(②配方明细!$A:$A,$A12,②配方明细!$M:$M),1) -> 29 | H12: =IFERROR(ROUND(D12/C12,0),0) -> 443 | I12: =IFERROR(ROUND(E12/C12,1),0) -> 40 | J12: =IFERROR(ROUND(F12/C12,1),0) -> 0 | K12: =IFERROR(ROUND(G12/C12,1),0) -> 29
A13: 彩椒炒鸡胸 | B13: 蛋白主菜 | C13: 1 | D13: =SUMIF(②配方明细!$A:$A,$A13,②配方明细!$J:$J) -> 314 | E13: =ROUND(SUMIF(②配方明细!$A:$A,$A13,②配方明细!$K:$K),1) -> 47.5 | F13: =ROUND(SUMIF(②配方明细!$A:$A,$A13,②配方明细!$L:$L),1) -> 9 | G13: =ROUND(SUMIF(②配方明细!$A:$A,$A13,②配方明细!$M:$M),1) -> 8.7 | H13: =IFERROR(ROUND(D13/C13,0),0) -> 314 | I13: =IFERROR(ROUND(E13/C13,1),0) -> 47.5 | J13: =IFERROR(ROUND(F13/C13,1),0) -> 9 | K13: =IFERROR(ROUND(G13/C13,1),0) -> 8.7
A14: 蔬菜
A15: 蒜蓉西兰花 | B15: 蔬菜 | C15: 1 | D15: =SUMIF(②配方明细!$A:$A,$A15,②配方明细!$J:$J) -> 112 | E15: =ROUND(SUMIF(②配方明细!$A:$A,$A15,②配方明细!$K:$K),1) -> 7 | F15: =ROUND(SUMIF(②配方明细!$A:$A,$A15,②配方明细!$L:$L),1) -> 17.5 | G15: =ROUND(SUMIF(②配方明细!$A:$A,$A15,②配方明细!$M:$M),1) -> 4 | H15: =IFERROR(ROUND(D15/C15,0),0) -> 112 | I15: =IFERROR(ROUND(E15/C15,1),0) -> 7 | J15: =IFERROR(ROUND(F15/C15,1),0) -> 17.5 | K15: =IFERROR(ROUND(G15/C15,1),0) -> 4
A16: 清炒菠菜 | B16: 蔬菜 | C16: 1 | D16: =SUMIF(②配方明细!$A:$A,$A16,②配方明细!$J:$J) -> 73 | E16: =ROUND(SUMIF(②配方明细!$A:$A,$A16,②配方明细!$K:$K),1) -> 5.8 | F16: =ROUND(SUMIF(②配方明细!$A:$A,$A16,②配方明细!$L:$L),1) -> 7.2 | G16: =ROUND(SUMIF(②配方明细!$A:$A,$A16,②配方明细!$M:$M),1) -> 3.8 | H16: =IFERROR(ROUND(D16/C16,0),0) -> 73 | I16: =IFERROR(ROUND(E16/C16,1),0) -> 5.8 | J16: =IFERROR(ROUND(F16/C16,1),0) -> 7.2 | K16: =IFERROR(ROUND(G16/C16,1),0) -> 3.8
A17: 凉拌黄瓜 | B17: 蔬菜 | C17: 1 | D17: =SUMIF(②配方明细!$A:$A,$A17,②配方明细!$J:$J) -> 39 | E17: =ROUND(SUMIF(②配方明细!$A:$A,$A17,②配方明细!$K:$K),1) -> 1.5 | F17: =ROUND(SUMIF(②配方明细!$A:$A,$A17,②配方明细!$L:$L),1) -> 8.9 | G17: =ROUND(SUMIF(②配方明细!$A:$A,$A17,②配方明细!$M:$M),1) -> 0.2 | H17: =IFERROR(ROUND(D17/C17,0),0) -> 39 | I17: =IFERROR(ROUND(E17/C17,1),0) -> 1.5 | J17: =IFERROR(ROUND(F17/C17,1),0) -> 8.9 | K17: =IFERROR(ROUND(G17/C17,1),0) -> 0.2
A18: 蒜蓉金针菇 | B18: 蔬菜 | C18: 1 | D18: =SUMIF(②配方明细!$A:$A,$A18,②配方明细!$J:$J) -> 60 | E18: =ROUND(SUMIF(②配方明细!$A:$A,$A18,②配方明细!$K:$K),1) -> 5 | F18: =ROUND(SUMIF(②配方明细!$A:$A,$A18,②配方明细!$L:$L),1) -> 10 | G18: =ROUND(SUMIF(②配方明细!$A:$A,$A18,②配方明细!$M:$M),1) -> 0.6 | H18: =IFERROR(ROUND(D18/C18,0),0) -> 60 | I18: =IFERROR(ROUND(E18/C18,1),0) -> 5 | J18: =IFERROR(ROUND(F18/C18,1),0) -> 10 | K18: =IFERROR(ROUND(G18/C18,1),0) -> 0.6
A19: 醋溜白菜 | B19: 蔬菜 | C19: 1 | D19: =SUMIF(②配方明细!$A:$A,$A19,②配方明细!$J:$J) -> 99 | E19: =ROUND(SUMIF(②配方明细!$A:$A,$A19,②配方明细!$K:$K),1) -> 3.4 | F19: =ROUND(SUMIF(②配方明细!$A:$A,$A19,②配方明细!$L:$L),1) -> 16.7 | G19: =ROUND(SUMIF(②配方明细!$A:$A,$A19,②配方明细!$M:$M),1) -> 3.3 | H19: =IFERROR(ROUND(D19/C19,0),0) -> 99 | I19: =IFERROR(ROUND(E19/C19,1),0) -> 3.4 | J19: =IFERROR(ROUND(F19/C19,1),0) -> 16.7 | K19: =IFERROR(ROUND(G19/C19,1),0) -> 3.3
A20: 凉拌豆腐 | B20: 蔬菜 | C20: 1 | D20: =SUMIF(②配方明细!$A:$A,$A20,②配方明细!$J:$J) -> 110 | E20: =ROUND(SUMIF(②配方明细!$A:$A,$A20,②配方明细!$K:$K),1) -> 10 | F20: =ROUND(SUMIF(②配方明细!$A:$A,$A20,②配方明细!$L:$L),1) -> 4 | G20: =ROUND(SUMIF(②配方明细!$A:$A,$A20,②配方明细!$M:$M),1) -> 5 | H20: =IFERROR(ROUND(D20/C20,0),0) -> 110 | I20: =IFERROR(ROUND(E20/C20,1),0) -> 10 | J20: =IFERROR(ROUND(F20/C20,1),0) -> 4 | K20: =IFERROR(ROUND(G20/C20,1),0) -> 5
A21: 汤
A22: 辣白菜豆腐汤 | B22: 汤 | C22: 3 | D22: =SUMIF(②配方明细!$A:$A,$A22,②配方明细!$J:$J) -> 357 | E22: =ROUND(SUMIF(②配方明细!$A:$A,$A22,②配方明细!$K:$K),1) -> 41.4 | F22: =ROUND(SUMIF(②配方明细!$A:$A,$A22,②配方明细!$L:$L),1) -> 13 | G22: =ROUND(SUMIF(②配方明细!$A:$A,$A22,②配方明细!$M:$M),1) -> 16.8 | H22: =IFERROR(ROUND(D22/C22,0),0) -> 119 | I22: =IFERROR(ROUND(E22/C22,1),0) -> 13.8 | J22: =IFERROR(ROUND(F22/C22,1),0) -> 4.3 | K22: =IFERROR(ROUND(G22/C22,1),0) -> 5.6 | L22: 贴纸菜
A23: 海带豆腐汤 | B23: 汤 | C23: 3 | D23: =SUMIF(②配方明细!$A:$A,$A23,②配方明细!$J:$J) -> 205 | E23: =ROUND(SUMIF(②配方明细!$A:$A,$A23,②配方明细!$K:$K),1) -> 19.7 | F23: =ROUND(SUMIF(②配方明细!$A:$A,$A23,②配方明细!$L:$L),1) -> 13 | G23: =ROUND(SUMIF(②配方明细!$A:$A,$A23,②配方明细!$M:$M),1) -> 9.6 | H23: =IFERROR(ROUND(D23/C23,0),0) -> 68 | I23: =IFERROR(ROUND(E23/C23,1),0) -> 6.6 | J23: =IFERROR(ROUND(F23/C23,1),0) -> 4.3 | K23: =IFERROR(ROUND(G23/C23,1),0) -> 3.2
A24: 番茄豆芽汤 | B24: 汤 | C24: 2 | D24: =SUMIF(②配方明细!$A:$A,$A24,②配方明细!$J:$J) -> 138 | E24: =ROUND(SUMIF(②配方明细!$A:$A,$A24,②配方明细!$K:$K),1) -> 11.1 | F24: =ROUND(SUMIF(②配方明细!$A:$A,$A24,②配方明细!$L:$L),1) -> 14.2 | G24: =ROUND(SUMIF(②配方明细!$A:$A,$A24,②配方明细!$M:$M),1) -> 5.4 | H24: =IFERROR(ROUND(D24/C24,0),0) -> 69 | I24: =IFERROR(ROUND(E24/C24,1),0) -> 5.6 | J24: =IFERROR(ROUND(F24/C24,1),0) -> 7.1 | K24: =IFERROR(ROUND(G24/C24,1),0) -> 2.7
A25: 萝卜牛肉汤 | B25: 汤 | C25: 4 | D25: =SUMIF(②配方明细!$A:$A,$A25,②配方明细!$J:$J) -> 510 | E25: =ROUND(SUMIF(②配方明细!$A:$A,$A25,②配方明细!$K:$K),1) -> 64.8 | F25: =ROUND(SUMIF(②配方明细!$A:$A,$A25,②配方明细!$L:$L),1) -> 12 | G25: =ROUND(SUMIF(②配方明细!$A:$A,$A25,②配方明细!$M:$M),1) -> 21.3 | H25: =IFERROR(ROUND(D25/C25,0),0) -> 128 | I25: =IFERROR(ROUND(E25/C25,1),0) -> 16.2 | J25: =IFERROR(ROUND(F25/C25,1),0) -> 3 | K25: =IFERROR(ROUND(G25/C25,1),0) -> 5.3
A26: 辣牛肉豆腐汤 | B26: 汤 | C26: 3 | D26: =SUMIF(②配方明细!$A:$A,$A26,②配方明细!$J:$J) -> 494 | E26: =ROUND(SUMIF(②配方明细!$A:$A,$A26,②配方明细!$K:$K),1) -> 61.6 | F26: =ROUND(SUMIF(②配方明细!$A:$A,$A26,②配方明细!$L:$L),1) -> 10 | G26: =ROUND(SUMIF(②配方明细!$A:$A,$A26,②配方明细!$M:$M),1) -> 23.5 | H26: =IFERROR(ROUND(D26/C26,0),0) -> 165 | I26: =IFERROR(ROUND(E26/C26,1),0) -> 20.5 | J26: =IFERROR(ROUND(F26/C26,1),0) -> 3.3 | K26: =IFERROR(ROUND(G26/C26,1),0) -> 7.8
A27: 主食
A28: 白米饭 | B28: 主食 | C28: 2 | D28: =SUMIF(②配方明细!$A:$A,$A28,②配方明细!$J:$J) -> 390 | E28: =ROUND(SUMIF(②配方明细!$A:$A,$A28,②配方明细!$K:$K),1) -> 8.1 | F28: =ROUND(SUMIF(②配方明细!$A:$A,$A28,②配方明细!$L:$L),1) -> 84 | G28: =ROUND(SUMIF(②配方明细!$A:$A,$A28,②配方明细!$M:$M),1) -> 0.9 | H28: =IFERROR(ROUND(D28/C28,0),0) -> 195 | I28: =IFERROR(ROUND(E28/C28,1),0) -> 4.1 | J28: =IFERROR(ROUND(F28/C28,1),0) -> 42 | K28: =IFERROR(ROUND(G28/C28,1),0) -> 0.5 | L28: 按拳数
A29: 蒸红薯 | B29: 主食 | C29: 1 | D29: =SUMIF(②配方明细!$A:$A,$A29,②配方明细!$J:$J) -> 225 | E29: =ROUND(SUMIF(②配方明细!$A:$A,$A29,②配方明细!$K:$K),1) -> 5 | F29: =ROUND(SUMIF(②配方明细!$A:$A,$A29,②配方明细!$L:$L),1) -> 52.5 | G29: =ROUND(SUMIF(②配方明细!$A:$A,$A29,②配方明细!$M:$M),1) -> 0.3 | H29: =IFERROR(ROUND(D29/C29,0),0) -> 225 | I29: =IFERROR(ROUND(E29/C29,1),0) -> 5 | J29: =IFERROR(ROUND(F29/C29,1),0) -> 52.5 | K29: =IFERROR(ROUND(G29/C29,1),0) -> 0.3
A30: 燕麦粥 | B30: 主食 | C30: 1 | D30: =SUMIF(②配方明细!$A:$A,$A30,②配方明细!$J:$J) -> 252 | E30: =ROUND(SUMIF(②配方明细!$A:$A,$A30,②配方明细!$K:$K),1) -> 12 | F30: =ROUND(SUMIF(②配方明细!$A:$A,$A30,②配方明细!$L:$L),1) -> 36.4 | G30: =ROUND(SUMIF(②配方明细!$A:$A,$A30,②配方明细!$M:$M),1) -> 6.8 | H30: =IFERROR(ROUND(D30/C30,0),0) -> 252 | I30: =IFERROR(ROUND(E30/C30,1),0) -> 12 | J30: =IFERROR(ROUND(F30/C30,1),0) -> 36.4 | K30: =IFERROR(ROUND(G30/C30,1),0) -> 6.8
A31: 洋葱牛肉饭 | B31: 主食 | C31: 1 | D31: =SUMIF(②配方明细!$A:$A,$A31,②配方明细!$J:$J) -> 528 | E31: =ROUND(SUMIF(②配方明细!$A:$A,$A31,②配方明细!$K:$K),1) -> 38 | F31: =ROUND(SUMIF(②配方明细!$A:$A,$A31,②配方明细!$L:$L),1) -> 65 | G31: =ROUND(SUMIF(②配方明细!$A:$A,$A31,②配方明细!$M:$M),1) -> 11.2 | H31: =IFERROR(ROUND(D31/C31,0),0) -> 528 | I31: =IFERROR(ROUND(E31/C31,1),0) -> 38 | J31: =IFERROR(ROUND(F31/C31,1),0) -> 65 | K31: =IFERROR(ROUND(G31/C31,1),0) -> 11.2
A32: 煲仔饭 | B32: 主食 | C32: 1 | D32: =SUMIF(②配方明细!$A:$A,$A32,②配方明细!$J:$J) -> 465 | E32: =ROUND(SUMIF(②配方明细!$A:$A,$A32,②配方明细!$K:$K),1) -> 36.7 | F32: =ROUND(SUMIF(②配方明细!$A:$A,$A32,②配方明细!$L:$L),1) -> 62 | G32: =ROUND(SUMIF(②配方明细!$A:$A,$A32,②配方明细!$M:$M),1) -> 6.7 | H32: =IFERROR(ROUND(D32/C32,0),0) -> 465 | I32: =IFERROR(ROUND(E32/C32,1),0) -> 36.7 | J32: =IFERROR(ROUND(F32/C32,1),0) -> 62 | K32: =IFERROR(ROUND(G32/C32,1),0) -> 6.7 | L32: 主食重,控份
A33: 南瓜饭 | B33: 主食 | C33: 1 | D33: =SUMIF(②配方明细!$A:$A,$A33,②配方明细!$J:$J) -> 295 | E33: =ROUND(SUMIF(②配方明细!$A:$A,$A33,②配方明细!$K:$K),1) -> 7.7 | F33: =ROUND(SUMIF(②配方明细!$A:$A,$A33,②配方明细!$L:$L),1) -> 66 | G33: =ROUND(SUMIF(②配方明细!$A:$A,$A33,②配方明细!$M:$M),1) -> 0.7 | H33: =IFERROR(ROUND(D33/C33,0),0) -> 295 | I33: =IFERROR(ROUND(E33/C33,1),0) -> 7.7 | J33: =IFERROR(ROUND(F33/C33,1),0) -> 66 | K33: =IFERROR(ROUND(G33/C33,1),0) -> 0.7
A34: 组装餐
A35: 沙拉碗 | B35: 组装餐 | C35: 1 | D35: =SUMIF(②配方明细!$A:$A,$A35,②配方明细!$J:$J) -> 257 | E35: =ROUND(SUMIF(②配方明细!$A:$A,$A35,②配方明细!$K:$K),1) -> 38.9 | F35: =ROUND(SUMIF(②配方明细!$A:$A,$A35,②配方明细!$L:$L),1) -> 15 | G35: =ROUND(SUMIF(②配方明细!$A:$A,$A35,②配方明细!$M:$M),1) -> 4.6 | H35: =IFERROR(ROUND(D35/C35,0),0) -> 257 | I35: =IFERROR(ROUND(E35/C35,1),0) -> 38.9 | J35: =IFERROR(ROUND(F35/C35,1),0) -> 15 | K35: =IFERROR(ROUND(G35/C35,1),0) -> 4.6 | L35: 蛋白可换
A36: 三明治 | B36: 组装餐 | C36: 1 | D36: =SUMIF(②配方明细!$A:$A,$A36,②配方明细!$J:$J) -> 346 | E36: =ROUND(SUMIF(②配方明细!$A:$A,$A36,②配方明细!$K:$K),1) -> 28.3 | F36: =ROUND(SUMIF(②配方明细!$A:$A,$A36,②配方明细!$L:$L),1) -> 33.2 | G36: =ROUND(SUMIF(②配方明细!$A:$A,$A36,②配方明细!$M:$M),1) -> 12.5 | H36: =IFERROR(ROUND(D36/C36,0),0) -> 346 | I36: =IFERROR(ROUND(E36/C36,1),0) -> 28.3 | J36: =IFERROR(ROUND(F36/C36,1),0) -> 33.2 | K36: =IFERROR(ROUND(G36/C36,1),0) -> 12.5 | L36: 料多则分2顿
A37: Pasta Salad | B37: 组装餐 | C37: 2 | D37: =SUMIF(②配方明细!$A:$A,$A37,②配方明细!$J:$J) -> 495 | E37: =ROUND(SUMIF(②配方明细!$A:$A,$A37,②配方明细!$K:$K),1) -> 34.5 | F37: =ROUND(SUMIF(②配方明细!$A:$A,$A37,②配方明细!$L:$L),1) -> 82.3 | G37: =ROUND(SUMIF(②配方明细!$A:$A,$A37,②配方明细!$M:$M),1) -> 2.3 | H37: =IFERROR(ROUND(D37/C37,0),0) -> 248 | I37: =IFERROR(ROUND(E37/C37,1),0) -> 17.3 | J37: =IFERROR(ROUND(F37/C37,1),0) -> 41.2 | K37: =IFERROR(ROUND(G37/C37,1),0) -> 1.2
A38: 柚子醋乌冬 | B38: 组装餐 | C38: 1 | D38: =SUMIF(②配方明细!$A:$A,$A38,②配方明细!$J:$J) -> 354 | E38: =ROUND(SUMIF(②配方明细!$A:$A,$A38,②配方明细!$K:$K),1) -> 14.1 | F38: =ROUND(SUMIF(②配方明细!$A:$A,$A38,②配方明细!$L:$L),1) -> 58.2 | G38: =ROUND(SUMIF(②配方明细!$A:$A,$A38,②配方明细!$M:$M),1) -> 6 | H38: =IFERROR(ROUND(D38/C38,0),0) -> 354 | I38: =IFERROR(ROUND(E38/C38,1),0) -> 14.1 | J38: =IFERROR(ROUND(F38/C38,1),0) -> 58.2 | K38: =IFERROR(ROUND(G38/C38,1),0) -> 6
A39: 北非蛋 | B39: 组装餐 | C39: 1 | D39: =SUMIF(②配方明细!$A:$A,$A39,②配方明细!$J:$J) -> 238 | E39: =ROUND(SUMIF(②配方明细!$A:$A,$A39,②配方明细!$K:$K),1) -> 15.4 | F39: =ROUND(SUMIF(②配方明细!$A:$A,$A39,②配方明细!$L:$L),1) -> 14.6 | G39: =ROUND(SUMIF(②配方明细!$A:$A,$A39,②配方明细!$M:$M),1) -> 13.3 | H39: =IFERROR(ROUND(D39/C39,0),0) -> 238 | I39: =IFERROR(ROUND(E39/C39,1),0) -> 15.4 | J39: =IFERROR(ROUND(F39/C39,1),0) -> 14.6 | K39: =IFERROR(ROUND(G39/C39,1),0) -> 13.3
A40: snack/加餐
...

Sheet ④餐目标
A1: ④ 餐目标（来自你的贴纸 · 做饭参考预算，对账放到「每日」层）
A2: 餐次 | B2: 热量目标kcal | C2: 蛋白目标g | D2: 构成要点 | E2: 备选/说明
A3: 早餐 | B3: 400-450 | C3: 20-30 | D3: 蛋白打底+碳水+水果 | E3: A:蛋+酸奶+燕麦+果 / B:蛋+豆浆+全麦+牛油果 / C(训练后):豆浆+蛋+香蕉
A4: 午餐 | B4: 600 | C4: — | D4: 米饭1拳+主菜1拳(150-200g)+蔬菜半盘 | E4: 主菜:三文鱼/鸡胸/瘦牛/虾/豆腐
A5: 晚餐 | B5: 500-600 | C5: — | D5: 米饭0.7-1拳+主菜偏瘦+蔬菜多 | E5: 晚训:训练后优先蛋白,碳水少量
A6: 加餐 | B6: — | C6: — | D6: 200g酸奶 / <15g坚果 / 苹果 / 牛奶 | E6: 训练后优先蛋白
A7: 每日合计目标
A8: 每日蛋白 | B8: — | C8: 110 | D8: 鸡胸/豆腐/牛肉/三文鱼/虾/希腊酸奶/豆浆 | E8: 贴纸:110g/天
A9: 每日碳水 | B9: — | C9: — | D9: 2-3拳/整天 | E9: 红薯/燕麦/糙米/黑米
A10: 每日脂肪 | B10: — | C10: — | D10: 牛油果+坚果(合计) | E10: —

Sheet ⑤采购清单
A1: ⑤ 本次采购清单
A2: 周期约10天 · 早餐6 · 正餐16-17 · 训练每天(力量4次)
A4: A. 这两天先吃（会坏的库存）
B5: 食材 | C5: 数量 | D5: 期限 | E5: 怎么处理
A6: □ | B6: 一顿青菜 | C6: 1顿量 | D6: 明天 | E6: 明天的配菜
A7: □ | B7: 海鲜菇 | C7: 半包 | D7: 2-3天内 | E7: 炒/汤，搭青菜
A8: □ | B8: 肉馅 | C8: 一点 | D8: 几天内 | E8: 并进番茄肉末或丢汤里清掉
A10: B. 库存排进本周（不坏、爱吃）→ 因此别买
B11: 食材 | C11: 数量 | D11: 排进 | E11: 因此别买
B12: 三文鱼 | C12: 2块 | D12: 2顿正餐 | E12: 鱼类蛋白
B13: everything贝果 | C13: 3个 | D13: 3顿早餐 | E13: 早餐贝果/面包
A15: C. 要买（黄色，可勾选）
B16: 项目 | C16: 规格/数量 | D16: 覆盖 | E16: 备注
B17: 蛋白
A18: □ | B18: 鸡胸肉 | C18: family pack ~2.5 lb | D18: 6-7顿 | E18: 想稳就拿3 lb
A19: □ | B19: 牛腩 或 瘦牛肉末 | C19: ~2 lb | D19: 番茄炖牛腩4顿+余
A20: □ | B20: 冷冻虾 | C20: 1 lb 袋 | D20: 2-3顿
A21: □ | B21: 老豆腐 | C21: 2 盒 | D21: 汤/凉拌/配菜 | E21: 蛋白紧可+1盒
A22: □ | B22: 鸡蛋 | C22: 2 打 | D22: 早餐+蛋菜 | E22: 耐放
B23: 主食
A24: □ | B24: 生米 | C24: 1 袋 2 lb | D24: 多顿 | E24: 耐放
A25: □ | B25: 红薯 | C25: 3-4 个 | D25: 碳水换口味 | E25: 耐放
A26: □ | B26: 燕麦 | C26: 1 桶 | D26: 3顿非贝果早餐 | E26: 耐放
B27: （面条） | C27: 不买 | D27: 库存6-8顿 | E27: 愿吃几顿你定，剩的别硬塞
B28: 蔬菜
A29: □ | B29: 洋葱/胡萝卜/卷心菜/彩椒 | C29: 各1（袋/颗） | D29: 耐放主力 | E29: 放得久
A30: □ | B30: 西兰花/番茄/黄瓜 | C30: 适量 | D30: 中等
A31: □ | B31: 菠菜 或 生菜 | C31: 1 盒 | D31: 沙拉 | E31: 5-7天内吃，可能第7天补一次
B32: 水果/加餐
A33: □ | B33: 香蕉 | C33: 1 小串 | D33: 训练后/早餐C | E33: 力量日用得上
A34: □ | B34: 苹果 | C34: 4-5 个 | D34: 加餐 | E34: 耐放
A35: □ | B35: 希腊酸奶 | C35: 32 oz 1桶 | D35: 早餐+加餐
A36: □ | B36: 混合坚果 | C36: 1 袋 | D36: 加餐<15g/次 | E36: 耐放
A37: □ | B37: 牛奶 | C37: half gallon | D37: 燕麦粥 | E37: 别买gallon，易剩
B38: 调味（缺才买）
A39: □ | B39: 咖喱块 | C39: 1 盒 | D39: 做咖喱鸡 | E39: 牌子差异大，看成分
B40: 油/醋/酱 | C40: 有就不买 | D40: —
A42: D. 提醒
A43: 按此量10天蛋白总量在每日110g目标的下沿偏紧。想稳：鸡胸拿3 lb 或 +1盒豆腐。
A45: 下一轮把这页接成自动：周计划选配方×锅数 → 引用②配方明细汇总食材需求(克) → 减食材库「久放可清点」的剩货 → 按包装取整。这次先手动跑通一遍。

Sheet ⑥库存表
A1: ⑥ 库存表 — 现有库存 + 6/3收据导入样本
A2: 状态: ✓在库可用 / ◐将尽先吃 / △库无待加 / ⚠计划外
A3: 对应食材 | B3: 类别 | C3: 当前数量 | D3: 单位 | E3: 存储 | F3: 入库日期 | G3: 久放可清点 | H3: 状态 | I3: 收据原名/来源 | J3: 单价$ | K3: 备注
A4: 现有库存（你冰箱现状）
A5: 鸡蛋 | B5: 蛋白质 | C5: 6 | D5: 个 | E5: 冷藏 | F5: 现有 | G5: =IFERROR(VLOOKUP(A5,①食材库!$B:$I,8,FALSE()),"") -> 是 | H5: ◐ | K5: 将尽
A6: 米饭(熟) | B6: 碳水 | C6: 1000 | D6: g生米 | E6: 常温 | F6: 现有 | G6: =IFERROR(VLOOKUP(A6,①食材库!$B:$I,8,FALSE()),"") -> 是 | H6: ✓
A7: 意面(干) | B7: 碳水 | C7: 600 | D7: g | E7: 常温 | F7: 现有 | G7: =IFERROR(VLOOKUP(A7,①食材库!$B:$I,8,FALSE()),"") -> 是 | H7: ✓ | K7: 够6-8顿
A8: 乌冬(熟) | B8: 碳水 | C8: 6 | D8: 顿 | E8: 冷藏 | F8: 现有 | G8: =IFERROR(VLOOKUP(A8,①食材库!$B:$I,8,FALSE()),"") -> 是 | H8: ◐ | I8: 面条库存 | K8: 6/26用100g,剩约6顿
A9: 三文鱼(生) | B9: 蛋白质 | C9: 1 | D9: 块 | E9: 冷冻 | F9: 现有 | G9: =IFERROR(VLOOKUP(A9,①食材库!$B:$I,8,FALSE()),"") -> 是 | H9: ✓ | K9: 6/26吃掉1块,剩1
A10: 金枪鱼罐头(水浸) | B10: 蛋白质 | C10: 1 | D10: 罐 | E10: 常温 | F10: 现有 | G10: =IFERROR(VLOOKUP(A10,①食材库!$B:$I,8,FALSE()),"") -> 是 | H10: ✓
A11: 金针菇/口蘑 | B11: 蔬菜 | C11: 0 | D11: 包 | E11: 冷藏 | F11: 现有 | G11: =IFERROR(VLOOKUP(A11,①食材库!$B:$I,8,FALSE()),"") -> 否 | H11: ✗ | I11: 海鲜菇 | K11: 6/26吃完
A12: 芥蓝/茼蒿/莴笋 | B12: 蔬菜 | C12: 0 | D12: 顿 | E12: 冷藏 | F12: 现有 | G12: =IFERROR(VLOOKUP(A12,①食材库!$B:$I,8,FALSE()),"") -> 否 | H12: ✗ | I12: 青菜 | K12: 6/26吃完
A13: —(待加:贝果) | B13: 碳水 | C13: 3 | D13: 个 | E13: 冷冻 | F13: 现有 | G13: =IFERROR(VLOOKUP(A13,①食材库!$B:$I,8,FALSE()),"") | H13: △ | I13: everything贝果 | K13: 库无,待加
A14: 6/3 Kroger 收据导入样本（演示映射）
A15: 三文鱼(生) | B15: 蛋白质 | C15: 454 | D15: g | E15: 冷冻 | F15: 6/3 | G15: =IFERROR(VLOOKUP(A15,①食材库!$B:$I,8,FALSE()),"") -> 是 | H15: ✓ | I15: Kroger Atlantic Salmon Fillet 16oz | J15: 12
A16: 牛油果 | B16: 脂肪 | C16: 2 | D16: 个 | E16: 冷藏 | F16: 6/3 | G16: =IFERROR(VLOOKUP(A16,①食材库!$B:$I,8,FALSE()),"") -> 否 | H16: ✓ | I16: Large Ripe Avocado ×2 | J16: 5
A17: 彩椒 | B17: 蔬菜 | C17: 1 | D17: 个 | E17: 冷藏 | F17: 6/3 | G17: =IFERROR(VLOOKUP(A17,①食材库!$B:$I,8,FALSE()),"") -> 否 | H17: ✓ | I17: Green Bell Pepper 1ct | J17: 1.29 | K17: 约150g
A18: 生菜 | B18: 蔬菜 | C18: 142 | D18: g | E18: 冷藏 | F18: 6/3 | G18: =IFERROR(VLOOKUP(A18,①食材库!$B:$I,8,FALSE()),"") -> 否 | H18: ✓ | I18: Baby Spring Mix 5oz | J18: 3.49 | K18: 近似映射沙拉菜
A19: —(待加:培根) | B19: 蛋白质 | C19: 454 | D19: g | E19: 冷藏 | F19: 6/3 | G19: =IFERROR(VLOOKUP(A19,①食材库!$B:$I,8,FALSE()),"") | H19: △ | I19: Hormel Bacon 16oz | J19: 7.99 | K19: 库无,128册有培根菜
A20: —(待加:白吐司) | B20: 碳水 | C20: 499 | D20: g | E20: 常温 | F20: 6/3 | G20: =IFERROR(VLOOKUP(A20,①食材库!$B:$I,8,FALSE()),"") | H20: △ | I20: Tuscan White Bread 17.6oz | J20: 3.49 | K20: 非全麦,库无
A21: —(待加:李子) | B21: 水果 | C21: 1 | D21: 个 | E21: 冷藏 | F21: 6/3 | G21: =IFERROR(VLOOKUP(A21,①食材库!$B:$I,8,FALSE()),"") | H21: △ | I21: Black Plum 1ct | J21: 1.7 | K21: 库无
A22: —(待加:桃子) | B22: 水果 | C22: 1 | D22: 个 | E22: 冷藏 | F22: 6/3 | G22: =IFERROR(VLOOKUP(A22,①食材库!$B:$I,8,FALSE()),"") | H22: △ | I22: Yellow Peach 1ct | J22: 2.03 | K22: 库无
A23: —(待加:柠檬) | B23: 调味 | C23: 1 | D23: 个 | E23: 冷藏 | F23: 6/3 | G23: =IFERROR(VLOOKUP(A23,①食材库!$B:$I,8,FALSE()),"") | H23: △ | I23: Large Lemon 1ct | J23: 0.85 | K23: 库无
A24: ⚠计划外:冷冻草莓(巧克力) | B24: 零食 | C24: 167 | D24: g | E24: 冷冻 | F24: 6/3 | G24: =IFERROR(VLOOKUP(A24,①食材库!$B:$I,8,FALSE()),"") | H24: ⚠ | I24: Tru Fru Frozen Strawberries White Choc 8oz | J24: 7.49 | K24: 6/27吃约60g
A25: ⚠计划外:冷冻香蕉(巧克力) | B25: 零食 | C25: 227 | D25: g | E25: 冷冻 | F25: 6/3 | G25: =IFERROR(VLOOKUP(A25,①食材库!$B:$I,8,FALSE()),"") | H25: ⚠ | I25: Tru Fru Frozen Bananas Dark Choc PB 8oz | J25: 7.49 | K25: 计划外零食
A27: 收据合计(对照Order Total $54.54核买多买少): | J27: =SUM(J4:J25) -> 52.82

Sheet ⑦每餐记录
A1: ⑦ 每餐记录 — 选配方·填份数，自动算这餐摄入（样本日 6/4）
A2: 一餐拆成几行（主菜+主食+蔬菜）。配方从③配方汇总取每份营养。份数=吃了几份。
A3: 日期 | B3: 餐次 | C3: 配方/食物 | D3: 份数 | E3: 查每份kcal | F3: 查每份P | G3: 查每份C | H3: 查每份F | I3: 本餐kcal | J3: 本餐P | K3: 本餐C | L3: 本餐F | M3: 备注
A4: 6/4 | B4: 早餐 | C4: 希腊酸奶配水果 | D4: 1 | E4: =IFERROR(VLOOKUP($C4,③配方汇总!$A:$K,8,FALSE()),0) -> 207 | F4: =IFERROR(VLOOKUP($C4,③配方汇总!$A:$K,9,FALSE()),0) -> 21.1 | G4: =IFERROR(VLOOKUP($C4,③配方汇总!$A:$K,10,FALSE()),0) -> 30.2 | H4: =IFERROR(VLOOKUP($C4,③配方汇总!$A:$K,11,FALSE()),0) -> 0.3 | I4: =ROUND($D4*E4,0) -> 207 | J4: =ROUND($D4*F4,1) -> 21.1 | K4: =ROUND($D4*G4,1) -> 30.2 | L4: =ROUND($D4*H4,1) -> 0.3 | M4: 训练后,优先蛋白
A5: 6/4 | B5: 早餐 | C5: 水煮蛋 | D5: 1 | E5: =IFERROR(VLOOKUP($C5,③配方汇总!$A:$K,8,FALSE()),0) -> 144 | F5: =IFERROR(VLOOKUP($C5,③配方汇总!$A:$K,9,FALSE()),0) -> 12.6 | G5: =IFERROR(VLOOKUP($C5,③配方汇总!$A:$K,10,FALSE()),0) -> 0.8 | H5: =IFERROR(VLOOKUP($C5,③配方汇总!$A:$K,11,FALSE()),0) -> 9.6 | I5: =ROUND($D5*E5,0) -> 144 | J5: =ROUND($D5*F5,1) -> 12.6 | K5: =ROUND($D5*G5,1) -> 0.8 | L5: =ROUND($D5*H5,1) -> 9.6 | M5: 2个蛋
A6: 6/4 | B6: 午餐 | C6: 番茄炖牛腩 | D6: 1 | E6: =IFERROR(VLOOKUP($C6,③配方汇总!$A:$K,8,FALSE()),0) -> 278 | F6: =IFERROR(VLOOKUP($C6,③配方汇总!$A:$K,9,FALSE()),0) -> 18.9 | G6: =IFERROR(VLOOKUP($C6,③配方汇总!$A:$K,10,FALSE()),0) -> 4.7 | H6: =IFERROR(VLOOKUP($C6,③配方汇总!$A:$K,11,FALSE()),0) -> 20.9 | I6: =ROUND($D6*E6,0) -> 278 | J6: =ROUND($D6*F6,1) -> 18.9 | K6: =ROUND($D6*G6,1) -> 4.7 | L6: =ROUND($D6*H6,1) -> 20.9 | M6: 吃1份(整锅1/4)
A7: 6/4 | B7: 午餐 | C7: 白米饭 | D7: 0.5 | E7: =IFERROR(VLOOKUP($C7,③配方汇总!$A:$K,8,FALSE()),0) -> 195 | F7: =IFERROR(VLOOKUP($C7,③配方汇总!$A:$K,9,FALSE()),0) -> 4.1 | G7: =IFERROR(VLOOKUP($C7,③配方汇总!$A:$K,10,FALSE()),0) -> 42 | H7: =IFERROR(VLOOKUP($C7,③配方汇总!$A:$K,11,FALSE()),0) -> 0.5 | I7: =ROUND($D7*E7,0) -> 98 | J7: =ROUND($D7*F7,1) -> 2.1 | K7: =ROUND($D7*G7,1) -> 21 | L7: =ROUND($D7*H7,1) -> 0.3 | M7: 1拳
A8: 6/4 | B8: 午餐 | C8: 蒜蓉西兰花 | D8: 1 | E8: =IFERROR(VLOOKUP($C8,③配方汇总!$A:$K,8,FALSE()),0) -> 112 | F8: =IFERROR(VLOOKUP($C8,③配方汇总!$A:$K,9,FALSE()),0) -> 7 | G8: =IFERROR(VLOOKUP($C8,③配方汇总!$A:$K,10,FALSE()),0) -> 17.5 | H8: =IFERROR(VLOOKUP($C8,③配方汇总!$A:$K,11,FALSE()),0) -> 4 | I8: =ROUND($D8*E8,0) -> 112 | J8: =ROUND($D8*F8,1) -> 7 | K8: =ROUND($D8*G8,1) -> 17.5 | L8: =ROUND($D8*H8,1) -> 4 | M8: 蔬菜够
A9: 6/4 | B9: 加餐 | C9: 坚果一份 | D9: 1 | E9: =IFERROR(VLOOKUP($C9,③配方汇总!$A:$K,8,FALSE()),0) -> 90 | F9: =IFERROR(VLOOKUP($C9,③配方汇总!$A:$K,9,FALSE()),0) -> 3 | G9: =IFERROR(VLOOKUP($C9,③配方汇总!$A:$K,10,FALSE()),0) -> 3 | H9: =IFERROR(VLOOKUP($C9,③配方汇总!$A:$K,11,FALSE()),0) -> 7.5 | I9: =ROUND($D9*E9,0) -> 90 | J9: =ROUND($D9*F9,1) -> 3 | K9: =ROUND($D9*G9,1) -> 3 | L9: =ROUND($D9*H9,1) -> 7.5 | M9: <15g
A10: 6/4 | B10: 晚餐 | C10: 香煎三文鱼 | D10: 1 | E10: =IFERROR(VLOOKUP($C10,③配方汇总!$A:$K,8,FALSE()),0) -> 443 | F10: =IFERROR(VLOOKUP($C10,③配方汇总!$A:$K,9,FALSE()),0) -> 40 | G10: =IFERROR(VLOOKUP($C10,③配方汇总!$A:$K,10,FALSE()),0) -> 0 | H10: =IFERROR(VLOOKUP($C10,③配方汇总!$A:$K,11,FALSE()),0) -> 29 | I10: =ROUND($D10*E10,0) -> 443 | J10: =ROUND($D10*F10,1) -> 40 | K10: =ROUND($D10*G10,1) -> 0 | L10: =ROUND($D10*H10,1) -> 29 | M10: 用库存三文鱼
A11: 6/4 | B11: 晚餐 | C11: 白米饭 | D11: 0.5 | E11: =IFERROR(VLOOKUP($C11,③配方汇总!$A:$K,8,FALSE()),0) -> 195 | F11: =IFERROR(VLOOKUP($C11,③配方汇总!$A:$K,9,FALSE()),0) -> 4.1 | G11: =IFERROR(VLOOKUP($C11,③配方汇总!$A:$K,10,FALSE()),0) -> 42 | H11: =IFERROR(VLOOKUP($C11,③配方汇总!$A:$K,11,FALSE()),0) -> 0.5 | I11: =ROUND($D11*E11,0) -> 98 | J11: =ROUND($D11*F11,1) -> 2.1 | K11: =ROUND($D11*G11,1) -> 21 | L11: =ROUND($D11*H11,1) -> 0.3 | M11: 1拳
A12: 6/4 | B12: 晚餐 | C12: 清炒菠菜 | D12: 1 | E12: =IFERROR(VLOOKUP($C12,③配方汇总!$A:$K,8,FALSE()),0) -> 73 | F12: =IFERROR(VLOOKUP($C12,③配方汇总!$A:$K,9,FALSE()),0) -> 5.8 | G12: =IFERROR(VLOOKUP($C12,③配方汇总!$A:$K,10,FALSE()),0) -> 7.2 | H12: =IFERROR(VLOOKUP($C12,③配方汇总!$A:$K,11,FALSE()),0) -> 3.8 | I12: =ROUND($D12*E12,0) -> 73 | J12: =ROUND($D12*F12,1) -> 5.8 | K12: =ROUND($D12*G12,1) -> 7.2 | L12: =ROUND($D12*H12,1) -> 3.8 | M12: 蔬菜够
C14: 当日合计 (6/4) | I14: =SUMIF($A4:$A12,"6/4",I4:I12) -> 1543 | J14: =ROUND(SUMIF($A4:$A12,"6/4",J4:J12),1) -> 112.6 | K14: =ROUND(SUMIF($A4:$A12,"6/4",K4:K12),1) -> 105.4 | L14: =ROUND(SUMIF($A4:$A12,"6/4",L4:L12),1) -> 75.7
C15: 每日目标 | I15: ~1900 | J15: 110 | M15: 蛋白110g是硬指标;热量减脂参考
A17: 6/25 | B17: 早餐 | C17: everything贝果 | D17: 1 | E17: =IFERROR(VLOOKUP($C17,③配方汇总!$A:$K,8,FALSE()),0) -> 285 | F17: =IFERROR(VLOOKUP($C17,③配方汇总!$A:$K,9,FALSE()),0) -> 10.5 | G17: =IFERROR(VLOOKUP($C17,③配方汇总!$A:$K,10,FALSE()),0) -> 56 | H17: =IFERROR(VLOOKUP($C17,③配方汇总!$A:$K,11,FALSE()),0) -> 3.8 | I17: =ROUND($D17*E17,0) -> 285 | J17: =ROUND($D17*F17,1) -> 10.5 | K17: =ROUND($D17*G17,1) -> 56 | L17: =ROUND($D17*H17,1) -> 3.8 | M17: 参考值,下次拍包装
A18: 6/25 | B18: 午餐 | C18: St Michel饼干 | D18: 3 | E18: =IFERROR(VLOOKUP($C18,③配方汇总!$A:$K,8,FALSE()),0) -> 170 | F18: =IFERROR(VLOOKUP($C18,③配方汇总!$A:$K,9,FALSE()),0) -> 2 | G18: =IFERROR(VLOOKUP($C18,③配方汇总!$A:$K,10,FALSE()),0) -> 23 | H18: =IFERROR(VLOOKUP($C18,③配方汇总!$A:$K,11,FALSE()),0) -> 7 | I18: =ROUND($D18*E18,0) -> 510 | J18: =ROUND($D18*F18,1) -> 6 | K18: =ROUND($D18*G18,1) -> 69 | L18: =ROUND($D18*H18,1) -> 21 | M18: 6片=3份(每份2片)
A19: 6/25 | B19: 晚餐 | C19: 金枪鱼意面 | D19: 1 | E19: =IFERROR(VLOOKUP($C19,③配方汇总!$A:$K,8,FALSE()),0) -> 513 | F19: =IFERROR(VLOOKUP($C19,③配方汇总!$A:$K,9,FALSE()),0) -> 30.4 | G19: =IFERROR(VLOOKUP($C19,③配方汇总!$A:$K,10,FALSE()),0) -> 74.9 | H19: =IFERROR(VLOOKUP($C19,③配方汇总!$A:$K,11,FALSE()),0) -> 10.4 | I19: =ROUND($D19*E19,0) -> 513 | J19: =ROUND($D19*F19,1) -> 30.4 | K19: =ROUND($D19*G19,1) -> 74.9 | L19: =ROUND($D19*H19,1) -> 10.4 | M19: 意面90/金枪鱼半罐/酱25/黄瓜/小番茄
C20: 当日合计 (6/25) | I20: =SUMIF($A17:$A19,"6/25",I17:I19) -> 1308 | J20: =ROUND(SUMIF($A17:$A19,"6/25",J17:J19),1) -> 46.9 | K20: =ROUND(SUMIF($A17:$A19,"6/25",K17:K19),1) -> 199.9 | L20: =ROUND(SUMIF($A17:$A19,"6/25",L17:L19),1) -> 35.2
C21: 每日目标 | I21: ~1900 | J21: 110 | M21: 蛋白110硬指标
A23: 6/26 | B23: 早午餐 | C23: 酸奶碗 | D23: 1 | E23: =IFERROR(VLOOKUP($C23,③配方汇总!$A:$K,8,FALSE()),0) -> 175 | F23: =IFERROR(VLOOKUP($C23,③配方汇总!$A:$K,9,FALSE()),0) -> 18.3 | G23: =IFERROR(VLOOKUP($C23,③配方汇总!$A:$K,10,FALSE()),0) -> 19.8 | H23: =IFERROR(VLOOKUP($C23,③配方汇总!$A:$K,11,FALSE()),0) -> 1.8 | I23: =ROUND($D23*E23,0) -> 175 | J23: =ROUND($D23*F23,1) -> 18.3 | K23: =ROUND($D23*G23,1) -> 19.8 | L23: =ROUND($D23*H23,1) -> 1.8 | M23: 燕麦20/牛奶20/无糖酸奶150
A24: 6/26 | B24: 晚餐 | C24: 三文鱼蔬菜面 | D24: 1 | E24: =IFERROR(VLOOKUP($C24,③配方汇总!$A:$K,8,FALSE()),0) -> 895 | F24: =IFERROR(VLOOKUP($C24,③配方汇总!$A:$K,9,FALSE()),0) -> 63.9 | G24: =IFERROR(VLOOKUP($C24,③配方汇总!$A:$K,10,FALSE()),0) -> 83 | H24: =IFERROR(VLOOKUP($C24,③配方汇总!$A:$K,11,FALSE()),0) -> 31.8 | I24: =ROUND($D24*E24,0) -> 895 | J24: =ROUND($D24*F24,1) -> 63.9 | K24: =ROUND($D24*G24,1) -> 83 | L24: =ROUND($D24*H24,1) -> 31.8 | M24: 清库存:三文鱼227/面100/青菜/海鲜菇
C25: 当日合计 (6/26) | I25: =SUMIF($A23:$A24,"6/26",I23:I24) -> 1070 | J25: =ROUND(SUMIF($A23:$A24,"6/26",J23:J24),1) -> 82.2 | K25: =ROUND(SUMIF($A23:$A24,"6/26",K23:K24),1) -> 102.8 | L25: =ROUND(SUMIF($A23:$A24,"6/26",L23:L24),1) -> 33.6
C26: 每日目标 | I26: ~1900 | J26: 110 | M26: 蛋白110硬指标
A28: 6/27 | B28: 早午餐 | C28: 牛奶燕麦 | D28: 1 | E28: =IFERROR(VLOOKUP($C28,③配方汇总!$A:$K,8,FALSE()),0) -> 265 | F28: =IFERROR(VLOOKUP($C28,③配方汇总!$A:$K,9,FALSE()),0) -> 11.6 | G28: =IFERROR(VLOOKUP($C28,③配方汇总!$A:$K,10,FALSE()),0) -> 40.7 | H28: =IFERROR(VLOOKUP($C28,③配方汇总!$A:$K,11,FALSE()),0) -> 6.5 | I28: =ROUND($D28*E28,0) -> 265 | J28: =ROUND($D28*F28,1) -> 11.6 | K28: =ROUND($D28*G28,1) -> 40.7 | L28: =ROUND($D28*H28,1) -> 6.5 | M28: 燕麦50/牛奶150
A29: 6/27 | B29: 加餐 | C29: 冷冻巧克力水果 | D29: 1 | E29: =IFERROR(VLOOKUP($C29,③配方汇总!$A:$K,8,FALSE()),0) -> 201 | F29: =IFERROR(VLOOKUP($C29,③配方汇总!$A:$K,9,FALSE()),0) -> 2.1 | G29: =IFERROR(VLOOKUP($C29,③配方汇总!$A:$K,10,FALSE()),0) -> 27 | H29: =IFERROR(VLOOKUP($C29,③配方汇总!$A:$K,11,FALSE()),0) -> 9.6 | I29: =ROUND($D29*E29,0) -> 201 | J29: =ROUND($D29*F29,1) -> 2.1 | K29: =ROUND($D29*G29,1) -> 27 | L29: =ROUND($D29*H29,1) -> 9.6 | M29: 剩货,你估200kcal,待拍标签
A30: 6/27 | B30: 晚餐 | C30: 金枪鱼意面(加彩椒蛋) | D30: 1 | E30: =IFERROR(VLOOKUP($C30,③配方汇总!$A:$K,8,FALSE()),0) -> 655 | F30: =IFERROR(VLOOKUP($C30,③配方汇总!$A:$K,9,FALSE()),0) -> 39 | G30: =IFERROR(VLOOKUP($C30,③配方汇总!$A:$K,10,FALSE()),0) -> 88.8 | H30: =IFERROR(VLOOKUP($C30,③配方汇总!$A:$K,11,FALSE()),0) -> 15.9 | I30: =ROUND($D30*E30,0) -> 655 | J30: =ROUND($D30*F30,1) -> 39 | K30: =ROUND($D30*G30,1) -> 88.8 | L30: =ROUND($D30*H30,1) -> 15.9 | M30: 上次基础+1.5彩椒+1蛋
C31: 当日合计 (6/27) | I31: =SUMIF($A28:$A30,"6/27",I28:I30) -> 1121 | J31: =ROUND(SUMIF($A28:$A30,"6/27",J28:J30),1) -> 52.7 | K31: =ROUND(SUMIF($A28:$A30,"6/27",K28:K30),1) -> 156.5 | L31: =ROUND(SUMIF($A28:$A30,"6/27",L28:L30),1) -> 32
C32: 每日目标 | I32: ~1900 | J32: 110 | M32: 蛋白110硬指标
A34: 6/28 | B34: 早午餐 | C34: 韩式辣炖牛肉 | D34: 1 | E34: =IFERROR(VLOOKUP($C34,③配方汇总!$A:$K,8,FALSE()),0) -> 748 | F34: =IFERROR(VLOOKUP($C34,③配方汇总!$A:$K,9,FALSE()),0) -> 37.7 | G34: =IFERROR(VLOOKUP($C34,③配方汇总!$A:$K,10,FALSE()),0) -> 53.1 | H34: =IFERROR(VLOOKUP($C34,③配方汇总!$A:$K,11,FALSE()),0) -> 44.4 | I34: =ROUND($D34*E34,0) -> 748 | J34: =ROUND($D34*F34,1) -> 37.7 | K34: =ROUND($D34*G34,1) -> 53.1 | L34: =ROUND($D34*H34,1) -> 44.4 | M34: 吃1/3锅=1份
A35: 6/28 | B35: 早午餐 | C35: 白米饭 | D35: 1.5 | E35: =IFERROR(VLOOKUP($C35,③配方汇总!$A:$K,8,FALSE()),0) -> 195 | F35: =IFERROR(VLOOKUP($C35,③配方汇总!$A:$K,9,FALSE()),0) -> 4.1 | G35: =IFERROR(VLOOKUP($C35,③配方汇总!$A:$K,10,FALSE()),0) -> 42 | H35: =IFERROR(VLOOKUP($C35,③配方汇总!$A:$K,11,FALSE()),0) -> 0.5 | I35: =ROUND($D35*E35,0) -> 293 | J35: =ROUND($D35*F35,1) -> 6.2 | K35: =ROUND($D35*G35,1) -> 63 | L35: =ROUND($D35*H35,1) -> 0.8 | M35: 1.5拳
A36: 6/28 | B36: 早午餐 | C36: 沙拉菜 | D36: 0.33 | E36: =IFERROR(VLOOKUP($C36,③配方汇总!$A:$K,8,FALSE()),0) -> 28 | F36: =IFERROR(VLOOKUP($C36,③配方汇总!$A:$K,9,FALSE()),0) -> 2.8 | G36: =IFERROR(VLOOKUP($C36,③配方汇总!$A:$K,10,FALSE()),0) -> 5.3 | H36: =IFERROR(VLOOKUP($C36,③配方汇总!$A:$K,11,FALSE()),0) -> 0.4 | I36: =ROUND($D36*E36,0) -> 9 | J36: =ROUND($D36*F36,1) -> 0.9 | K36: =ROUND($D36*G36,1) -> 1.7 | L36: =ROUND($D36*H36,1) -> 0.1 | M36: 1/3盒
A37: 6/28 | B37: 早午餐 | C37: 蓝莓 | D37: 0.25 | E37: =IFERROR(VLOOKUP($C37,③配方汇总!$A:$K,8,FALSE()),0) -> 97 | F37: =IFERROR(VLOOKUP($C37,③配方汇总!$A:$K,9,FALSE()),0) -> 1.2 | G37: =IFERROR(VLOOKUP($C37,③配方汇总!$A:$K,10,FALSE()),0) -> 23.8 | H37: =IFERROR(VLOOKUP($C37,③配方汇总!$A:$K,11,FALSE()),0) -> 0.5 | I37: =ROUND($D37*E37,0) -> 24 | J37: =ROUND($D37*F37,1) -> 0.3 | K37: =ROUND($D37*G37,1) -> 6 | L37: =ROUND($D37*H37,1) -> 0.1 | M37: 1/4盒
A38: 6/28 | B38: 早午餐 | C38: 布拉塔 | D38: 0.25 | E38: =IFERROR(VLOOKUP($C38,③配方汇总!$A:$K,8,FALSE()),0) -> 375 | F38: =IFERROR(VLOOKUP($C38,③配方汇总!$A:$K,9,FALSE()),0) -> 15 | G38: =IFERROR(VLOOKUP($C38,③配方汇总!$A:$K,10,FALSE()),0) -> 3.8 | H38: =IFERROR(VLOOKUP($C38,③配方汇总!$A:$K,11,FALSE()),0) -> 33.8 | I38: =ROUND($D38*E38,0) -> 94 | J38: =ROUND($D38*F38,1) -> 3.8 | K38: =ROUND($D38*G38,1) -> 1 | L38: =ROUND($D38*H38,1) -> 8.5 | M38: 1/4个
A39: 6/28 | B39: 早午餐 | C39: 桃子 | D39: 1 | E39: =IFERROR(VLOOKUP($C39,③配方汇总!$A:$K,8,FALSE()),0) -> 59 | F39: =IFERROR(VLOOKUP($C39,③配方汇总!$A:$K,9,FALSE()),0) -> 1.4 | G39: =IFERROR(VLOOKUP($C39,③配方汇总!$A:$K,10,FALSE()),0) -> 15 | H39: =IFERROR(VLOOKUP($C39,③配方汇总!$A:$K,11,FALSE()),0) -> 0.5 | I39: =ROUND($D39*E39,0) -> 59 | J39: =ROUND($D39*F39,1) -> 1.4 | K39: =ROUND($D39*G39,1) -> 15 | L39: =ROUND($D39*H39,1) -> 0.5 | M39: 1个
A40: 6/28 | B40: 晚餐 | C40: 布拉塔 | D40: 0.25 | E40: =IFERROR(VLOOKUP($C40,③配方汇总!$A:$K,8,FALSE()),0) -> 375 | F40: =IFERROR(VLOOKUP($C40,③配方汇总!$A:$K,9,FALSE()),0) -> 15 | G40: =IFERROR(VLOOKUP($C40,③配方汇总!$A:$K,10,FALSE()),0) -> 3.8 | H40: =IFERROR(VLOOKUP($C40,③配方汇总!$A:$K,11,FALSE()),0) -> 33.8 | I40: =ROUND($D40*E40,0) -> 94 | J40: =ROUND($D40*F40,1) -> 3.8 | K40: =ROUND($D40*G40,1) -> 1 | L40: =ROUND($D40*H40,1) -> 8.5 | M40: 1/4个
A41: 6/28 | B41: 晚餐 | C41: 蓝莓 | D41: 0.25 | E41: =IFERROR(VLOOKUP($C41,③配方汇总!$A:$K,8,FALSE()),0) -> 97 | F41: =IFERROR(VLOOKUP($C41,③配方汇总!$A:$K,9,FALSE()),0) -> 1.2 | G41: =IFERROR(VLOOKUP($C41,③配方汇总!$A:$K,10,FALSE()),0) -> 23.8 | H41: =IFERROR(VLOOKUP($C41,③配方汇总!$A:$K,11,FALSE()),0) -> 0.5 | I41: =ROUND($D41*E41,0) -> 24 | J41: =ROUND($D41*F41,1) -> 0.3 | K41: =ROUND($D41*G41,1) -> 6 | L41: =ROUND($D41*H41,1) -> 0.1 | M41: 1/4盒
A42: 6/28 | B42: 加餐 | C42: 桃子 | D42: 1 | E42: =IFERROR(VLOOKUP($C42,③配方汇总!$A:$K,8,FALSE()),0) -> 59 | F42: =IFERROR(VLOOKUP($C42,③配方汇总!$A:$K,9,FALSE()),0) -> 1.4 | G42: =IFERROR(VLOOKUP($C42,③配方汇总!$A:$K,10,FALSE()),0) -> 15 | H42: =IFERROR(VLOOKUP($C42,③配方汇总!$A:$K,11,FALSE()),0) -> 0.5 | I42: =ROUND($D42*E42,0) -> 59 | J42: =ROUND($D42*F42,1) -> 1.4 | K42: =ROUND($D42*G42,1) -> 15 | L42: =ROUND($D42*H42,1) -> 0.5 | M42: 1个
A43: 6/28 | B43: 加餐 | C43: 蛋糕(外食) | D43: 1 | E43: =IFERROR(VLOOKUP($C43,③配方汇总!$A:$K,8,FALSE()),0) -> 400 | F43: =IFERROR(VLOOKUP($C43,③配方汇总!$A:$K,9,FALSE()),0) -> 5 | G43: =IFERROR(VLOOKUP($C43,③配方汇总!$A:$K,10,FALSE()),0) -> 50 | H43: =IFERROR(VLOOKUP($C43,③配方汇总!$A:$K,11,FALSE()),0) -> 20 | I43: =ROUND($D43*E43,0) -> 400 | J43: =ROUND($D43*F43,1) -> 5 | K43: =ROUND($D43*G43,1) -> 50 | L43: =ROUND($D43*H43,1) -> 20 | M43: 外食,预估400kcal
C44: 当日合计 (6/28) | I44: =SUMIF($A34:$A43,"6/28",I34:I43) -> 1804 | J44: =ROUND(SUMIF($A34:$A43,"6/28",J34:J43),1) -> 60.8 | K44: =ROUND(SUMIF($A34:$A43,"6/28",K34:K43),1) -> 211.8 | L44: =ROUND(SUMIF($A34:$A43,"6/28",L34:L43),1) -> 83.5
C45: 每日目标 | I45: ~1900 | J45: 110 | M45: 蛋白110硬指标
